Workbook

Sheet V0.5
A1: 대상웰라이프_WBS
A2: ▥ Last update : | B2: 45672
A3: 구분 | C3: 세부 업무 항목 | D3: 담당 | E3: 시작일 | F3: 종료일 | G3: 기간 | H3: 날짜기준 진척률 | I3: 실제 진척률 | J3: 1월 | AF3: 2월 | AZ3: 3월 | BW3: 4월 | CQ3: 5월 | DN3: 6월 | EJ3: 7월 | FE3: 8월 | GB3: 9월 | GW3: 10월 | HS3: 11월 | IO3: 12월 | JJ3: 1월 | KF3: 2월 | KZ3: 3월 | LW3: 4월 | MQ3: 5월 | NN3: 6월 | OJ3: 7월 | PE3: 8월 | QB3: 9월 | QW3: 10월 | RS3: 11월 | SO3: 12월
J4: 45292 | K4: =J4+1 -> 45293 | L4: =K4+1 -> 45294 | M4: =L4+1 -> 45295 | N4: =M4+1 -> 45296 | O4: =N4+3 -> 45299 | P4: =O4+1 -> 45300 | Q4: =P4+1 -> 45301 | R4: =Q4+1 -> 45302 | S4: =R4+1 -> 45303 | T4: =S4+3 -> 45306 | U4: =T4+1 -> 45307 | V4: =U4+1 -> 45308 | W4: =V4+1 -> 45309 | X4: =W4+1 -> 45310 | Y4: =X4+3 -> 45313 | Z4: =Y4+1 -> 45314 | AA4: =Z4+1 -> 45315 | AB4: =AA4+1 -> 45316 | AC4: =AB4+1 -> 45317 | AD4: =AC4+3 -> 45320 | AE4: =AD4+1 -> 45321 | AF4: =AE4+1 -> 45322 | AG4: =AF4+1 -> 45323 | AH4: =AG4+1 -> 45324 | AI4: =AH4+3 -> 45327 | AJ4: =AI4+1 -> 45328 | AK4: =AJ4+1 -> 45329 | AL4: =AK4+1 -> 45330 | AM4: =AL4+1 -> 45331 | AN4: =AM4+3 -> 45334 | AO4: =AN4+1 -> 45335 | AP4: =AO4+1 -> 45336 | AQ4: =AP4+1 -> 45337 | AR4: =AQ4+1 -> 45338 | AS4: =AR4+3 -> 45341 | AT4: =AS4+1 -> 45342 | AU4: =AT4+1 -> 45343 | AV4: =AU4+1 -> 45344 | AW4: =AV4+1 -> 45345 | AX4: =AW4+3 -> 45348 | AY4: =AX4+1 -> 45349 | AZ4: =AY4+1 -> 45350 | BA4: =AZ4+1 -> 45351 | BB4: =BA4+1 -> 45352 | BC4: =BB4+3 -> 45355 | BD4: =BC4+1 -> 45356 | BE4: =BD4+1 -> 45357 | BF4: =BE4+1 -> 45358 | BG4: =BF4+1 -> 45359 | BH4: =BG4+3 -> 45362 | BI4: =BH4+1 -> 45363 | BJ4: =BI4+1 -> 45364 | BK4: =BJ4+1 -> 45365 | BL4: =BK4+1 -> 45366 | BM4: =BL4+3 -> 45369 | BN4: =BM4+1 -> 45370 | BO4: =BN4+1 -> 45371 | BP4: =BO4+1 -> 45372 | BQ4: =BP4+1 -> 45373 | BR4: =BQ4+3 -> 45376 | BS4: =BR4+1 -> 45377 | BT4: =BS4+1 -> 45378 | BU4: =BT4+1 -> 45379 | BV4: =BU4+1 -> 45380 | BW4: =BV4+3 -> 45383 | BX4: =BW4+1 -> 45384 | BY4: =BX4+1 -> 45385 | BZ4: =BY4+1 -> 45386 | CA4: =BZ4+1 -> 45387 | CB4: =CA4+3 -> 45390 | CC4: =CB4+1 -> 45391 | CD4: =CC4+1 -> 45392 | CE4: =CD4+1 -> 45393 | CF4: =CE4+1 -> 45394 | CG4: =CF4+3 -> 45397 | CH4: =CG4+1 -> 45398 | CI4: =CH4+1 -> 45399 | CJ4: =CI4+1 -> 45400 | CK4: =CJ4+1 -> 45401 | CL4: =CK4+3 -> 45404 | CM4: =CL4+1 -> 45405 | CN4: =CM4+1 -> 45406 | CO4: =CN4+1 -> 45407 | CP4: =CO4+1 -> 45408 | CQ4: =CP4+3 -> 45411 | CR4: =CQ4+1 -> 45412 | CS4: =CR4+1 -> 45413 | CT4: =CS4+1 -> 45414 | CU4: =CT4+1 -> 45415 | CV4: =CU4+3 -> 45418 | CW4: =CV4+1 -> 45419 | CX4: =CW4+1 -> 45420 | CY4: =CX4+1 -> 45421 | CZ4: =CY4+1 -> 45422 | DA4: =CZ4+3 -> 45425 | DB4: =DA4+1 -> 45426 | DC4: =DB4+1 -> 45427 | DD4: =DC4+1 -> 45428 | DE4: =DD4+1 -> 45429 | DF4: =DE4+3 -> 45432 | DG4: =DF4+1 -> 45433 | DH4: =DG4+1 -> 45434 | DI4: =DH4+1 -> 45435 | DJ4: =DI4+1 -> 45436 | DK4: =DJ4+3 -> 45439 | DL4: =DK4+1 -> 45440 | DM4: =DL4+1 -> 45441 | DN4: =DM4+1 -> 45442 | DO4: =DN4+1 -> 45443 | DP4: =DO4+3 -> 45446 | DQ4: =DP4+1 -> 45447 | DR4: =DQ4+1 -> 45448 | DS4: =DR4+1 -> 45449 | DT4: =DS4+1 -> 45450 | DU4: =DT4+3 -> 45453 | DV4: =DU4+1 -> 45454 | DW4: =DV4+1 -> 45455 | DX4: =DW4+1 -> 45456 | DY4: =DX4+1 -> 45457 | DZ4: =DY4+3 -> 45460 | EA4: =DZ4+1 -> 45461 | EB4: =EA4+1 -> 45462 | EC4: =EB4+1 -> 45463 | ED4: =EC4+1 -> 45464 | EE4: =ED4+3 -> 45467 | EF4: =EE4+1 -> 45468 | EG4: =EF4+1 -> 45469 | EH4: =EG4+1 -> 45470 | EI4: =EH4+1 -> 45471 | EJ4: =EI4+3 -> 45474 | EK4: =EJ4+1 -> 45475 | EL4: =EK4+1 -> 45476 | EM4: =EL4+1 -> 45477 | EN4: =EM4+1 -> 45478 | EO4: =EN4+3 -> 45481 | EP4: =EO4+1 -> 45482 | EQ4: =EP4+1 -> 45483 | ER4: =EQ4+1 -> 45484 | ES4: =ER4+1 -> 45485 | ET4: =ES4+3 -> 45488 | EU4: =ET4+1 -> 45489 | EV4: =EU4+1 -> 45490 | EW4: =EV4+1 -> 45491 | EX4: =EW4+1 -> 45492 | EY4: =EX4+3 -> 45495 | EZ4: =EY4+1 -> 45496 | FA4: =EZ4+1 -> 45497 | FB4: =FA4+1 -> 45498 | FC4: =FB4+1 -> 45499 | FD4: =FC4+3 -> 45502 | FE4: =FD4+1 -> 45503 | FF4: =FE4+1 -> 45504 | FG4: =FF4+1 -> 45505 | FH4: =FG4+1 -> 45506 | FI4: =FH4+3 -> 45509 | FJ4: =FI4+1 -> 45510 | FK4: =FJ4+1 -> 45511 | FL4: =FK4+1 -> 45512 | FM4: =FL4+1 -> 45513 | FN4: =FM4+3 -> 45516 | FO4: =FN4+1 -> 45517 | FP4: =FO4+1 -> 45518 | FQ4: =FP4+1 -> 45519 | FR4: =FQ4+1 -> 45520 | FS4: =FR4+3 -> 45523 | FT4: =FS4+1 -> 45524 | FU4: =FT4+1 -> 45525 | FV4: =FU4+1 -> 45526 | FW4: =FV4+1 -> 45527 | FX4: =FW4+3 -> 45530 | FY4: =FX4+1 -> 45531 | FZ4: =FY4+1 -> 45532 | GA4: =FZ4+1 -> 45533 | GB4: =GA4+1 -> 45534 | GC4: =GB4+3 -> 45537 | GD4: =GC4+1 -> 45538 | GE4: =GD4+1 -> 45539 | GF4: =GE4+1 -> 45540 | GG4: =GF4+1 -> 45541 | GH4: =GG4+3 -> 45544 | GI4: =GH4+1 -> 45545 | GJ4: =GI4+1 -> 45546 | GK4: =GJ4+1 -> 45547 | GL4: =GK4+1 -> 45548 | GM4: =GL4+3 -> 45551 | GN4: =GM4+1 -> 45552 | GO4: =GN4+1 -> 45553 | GP4: =GO4+1 -> 45554 | GQ4: =GP4+1 -> 45555 | GR4: =GQ4+3 -> 45558 | GS4: =GR4+1 -> 45559 | GT4: =GS4+1 -> 45560 | GU4: =GT4+1 -> 45561 | GV4: =GU4+1 -> 45562 | GW4: =GV4+3 -> 45565 | GX4: =GW4+1 -> 45566 | GY4: =GX4+1 -> 45567 | GZ4: =GY4+1 -> 45568 | HA4: =GZ4+1 -> 45569 | HB4: =HA4+3 -> 45572 | HC4: =HB4+1 -> 45573 | HD4: =HC4+1 -> 45574 | HE4: =HD4+1 -> 45575 | HF4: =HE4+1 -> 45576 | HG4: =HF4+3 -> 45579 | HH4: =HG4+1 -> 45580 | HI4: =HH4+1 -> 45581 | HJ4: =HI4+1 -> 45582 | HK4: =HJ4+1 -> 45583 | HL4: =HK4+3 -> 45586 | HM4: =HL4+1 -> 45587 | HN4: =HM4+1 -> 45588 | HO4: =HN4+1 -> 45589 | HP4: =HO4+1 -> 45590 | HQ4: =HP4+3 -> 45593 | HR4: =HQ4+1 -> 45594 | HS4: =HR4+1 -> 45595 | HT4: =HS4+1 -> 45596 | HU4: =HT4+1 -> 45597 | HV4: =HU4+3 -> 45600 | HW4: =HV4+1 -> 45601 | HX4: =HW4+1 -> 45602 | HY4: =HX4+1 -> 45603 | HZ4: =HY4+1 -> 45604 | IA4: =HZ4+3 -> 45607 | IB4: =IA4+1 -> 45608 | IC4: =IB4+1 -> 45609 | ID4: =IC4+1 -> 45610 | IE4: =ID4+1 -> 45611 | IF4: =IE4+3 -> 45614 | IG4: =IF4+1 -> 45615 | IH4: =IG4+1 -> 45616 | II4: =IH4+1 -> 45617 | IJ4: =II4+1 -> 45618 | IK4: =IJ4+3 -> 45621 | IL4: =IK4+1 -> 45622 | IM4: =IL4+1 -> 45623 | IN4: =IM4+1 -> 45624 | IO4: =IN4+1 -> 45625 | IP4: =IO4+3 -> 45628 | IQ4: =IP4+1 -> 45629 | IR4: =IQ4+1 -> 45630 | IS4: =IR4+1 -> 45631 | IT4: =IS4+1 -> 45632 | IU4: =IT4+3 -> 45635 | IV4: =IU4+1 -> 45636 | IW4: =IV4+1 -> 45637 | IX4: =IW4+1 -> 45638 | IY4: =IX4+1 -> 45639 | IZ4: =IY4+3 -> 45642 | JA4: =IZ4+1 -> 45643 | JB4: =JA4+1 -> 45644 | JC4: =JB4+1 -> 45645 | JD4: =JC4+1 -> 45646 | JE4: =JD4+3 -> 45649 | JF4: =JE4+1 -> 45650 | JG4: =JF4+1 -> 45651 | JH4: =JG4+1 -> 45652 | JI4: =JH4+1 -> 45653 | JJ4: =JI4+3 -> 45656 | JK4: =JJ4+1 -> 45657 | JL4: =JK4+1 -> 45658 | JM4: =JL4+1 -> 45659 | JN4: =JM4+1 -> 45660 | JO4: =JN4+3 -> 45663 | JP4: =JO4+1 -> 45664 | JQ4: =JP4+1 -> 45665 | JR4: =JQ4+1 -> 45666 | JS4: =JR4+1 -> 45667 | JT4: =JS4+3 -> 45670 | JU4: =JT4+1 -> 45671 | JV4: =JU4+1 -> 45672 | JW4: =JV4+1 -> 45673 | JX4: =JW4+1 -> 45674 | JY4: =JX4+3 -> 45677 | JZ4: =JY4+1 -> 45678 | KA4: =JZ4+1 -> 45679 | KB4: =KA4+1 -> 45680 | KC4: =KB4+1 -> 45681 | KD4: =KC4+3 -> 45684 | KE4: =KD4+1 -> 45685 | KF4: =KE4+1 -> 45686 | KG4: =KF4+1 -> 45687 | KH4: =KG4+1 -> 45688 | KI4: =KH4+3 -> 45691 | KJ4: =KI4+1 -> 45692 | KK4: =KJ4+1 -> 45693 | KL4: =KK4+1 -> 45694 | KM4: =KL4+1 -> 45695 | KN4: =KM4+3 -> 45698 | KO4: =KN4+1 -> 45699 | KP4: =KO4+1 -> 45700 | KQ4: =KP4+1 -> 45701 | KR4: =KQ4+1 -> 45702 | KS4: =KR4+3 -> 45705 | KT4: =KS4+1 -> 45706 | KU4: =KT4+1 -> 45707 | KV4: =KU4+1 -> 45708 | KW4: =KV4+1 -> 45709 | KX4: =KW4+3 -> 45712 | KY4: =KX4+1 -> 45713 | KZ4: =KY4+1 -> 45714 | LA4: =KZ4+1 -> 45715 | LB4: =LA4+1 -> 45716 | LC4: =LB4+3 -> 45719 | LD4: =LC4+1 -> 45720 | LE4: =LD4+1 -> 45721 | LF4: =LE4+1 -> 45722 | LG4: =LF4+1 -> 45723 | LH4: =LG4+3 -> 45726 | LI4: =LH4+1 -> 45727 | LJ4: =LI4+1 -> 45728 | LK4: =LJ4+1 -> 45729 | LL4: =LK4+1 -> 45730 | LM4: =LL4+3 -> 45733 | LN4: =LM4+1 -> 45734 | LO4: =LN4+1 -> 45735 | LP4: =LO4+1 -> 45736 | LQ4: =LP4+1 -> 45737 | LR4: =LQ4+3 -> 45740 | LS4: =LR4+1 -> 45741 | LT4: =LS4+1 -> 45742 | LU4: =LT4+1 -> 45743 | LV4: =LU4+1 -> 45744 | LW4: =LV4+3 -> 45747 | LX4: =LW4+1 -> 45748 | LY4: =LX4+1 -> 45749 | LZ4: =LY4+1 -> 45750 | MA4: =LZ4+1 -> 45751 | MB4: =MA4+3 -> 45754 | MC4: =MB4+1 -> 45755 | MD4: =MC4+1 -> 45756 | ME4: =MD4+1 -> 45757 | MF4: =ME4+1 -> 45758 | MG4: =MF4+3 -> 45761 | MH4: =MG4+1 -> 45762 | MI4: =MH4+1 -> 45763 | MJ4: =MI4+1 -> 45764 | MK4: =MJ4+1 -> 45765 | ML4: =MK4+3 -> 45768 | MM4: =ML4+1 -> 45769 | MN4: =MM4+1 -> 45770 | MO4: =MN4+1 -> 45771 | MP4: =MO4+1 -> 45772 | MQ4: =MP4+3 -> 45775 | MR4: =MQ4+1 -> 45776 | MS4: =MR4+1 -> 45777 | MT4: =MS4+1 -> 45778 | MU4: =MT4+1 -> 45779 | MV4: =MU4+3 -> 45782 | MW4: =MV4+1 -> 45783 | MX4: =MW4+1 -> 45784 | MY4: =MX4+1 -> 45785 | MZ4: =MY4+1 -> 45786 | NA4: =MZ4+3 -> 45789 | NB4: =NA4+1 -> 45790 | NC4: =NB4+1 -> 45791 | ND4: =NC4+1 -> 45792 | NE4: =ND4+1 -> 45793 | NF4: =NE4+3 -> 45796 | NG4: =NF4+1 -> 45797 | NH4: =NG4+1 -> 45798 | NI4: =NH4+1 -> 45799 | NJ4: =NI4+1 -> 45800 | NK4: =NJ4+3 -> 45803 | NL4: =NK4+1 -> 45804 | NM4: =NL4+1 -> 45805 | NN4: =NM4+1 -> 45806 | NO4: =NN4+1 -> 45807 | NP4: =NO4+3 -> 45810 | NQ4: =NP4+1 -> 45811 | NR4: =NQ4+1 -> 45812 | NS4: =NR4+1 -> 45813 | NT4: =NS4+1 -> 45814 | NU4: =NT4+3 -> 45817 | NV4: =NU4+1 -> 45818 | NW4: =NV4+1 -> 45819 | NX4: =NW4+1 -> 45820 | NY4: =NX4+1 -> 45821 | NZ4: =NY4+3 -> 45824 | OA4: =NZ4+1 -> 45825 | OB4: =OA4+1 -> 45826 | OC4: =OB4+1 -> 45827 | OD4: =OC4+1 -> 45828 | OE4: =OD4+3 -> 45831 | OF4: =OE4+1 -> 45832 | OG4: =OF4+1 -> 45833 | OH4: =OG4+1 -> 45834 | OI4: =OH4+1 -> 45835 | OJ4: =OI4+3 -> 45838 | OK4: =OJ4+1 -> 45839 | OL4: =OK4+1 -> 45840 | OM4: =OL4+1 -> 45841 | ON4: =OM4+1 -> 45842 | OO4: =ON4+3 -> 45845 | OP4: =OO4+1 -> 45846 | OQ4: =OP4+1 -> 45847 | OR4: =OQ4+1 -> 45848 | OS4: =OR4+1 -> 45849 | OT4: =OS4+3 -> 45852 | OU4: =OT4+1 -> 45853 | OV4: =OU4+1 -> 45854 | OW4: =OV4+1 -> 45855 | OX4: =OW4+1 -> 45856 | OY4: =OX4+3 -> 45859 | OZ4: =OY4+1 -> 45860 | PA4: =OZ4+1 -> 45861 | PB4: =PA4+1 -> 45862 | PC4: =PB4+1 -> 45863 | PD4: =PC4+3 -> 45866 | PE4: =PD4+1 -> 45867 | PF4: =PE4+1 -> 45868 | PG4: =PF4+1 -> 45869 | PH4: =PG4+1 -> 45870 | PI4: =PH4+3 -> 45873 | PJ4: =PI4+1 -> 45874 | PK4: =PJ4+1 -> 45875 | PL4: =PK4+1 -> 45876 | PM4: =PL4+1 -> 45877 | PN4: =PM4+3 -> 45880 | PO4: =PN4+1 -> 45881 | PP4: =PO4+1 -> 45882 | PQ4: =PP4+1 -> 45883 | PR4: =PQ4+1 -> 45884 | PS4: =PR4+3 -> 45887 | PT4: =PS4+1 -> 45888 | PU4: =PT4+1 -> 45889 | PV4: =PU4+1 -> 45890 | PW4: =PV4+1 -> 45891 | PX4: =PW4+3 -> 45894 | PY4: =PX4+1 -> 45895 | PZ4: =PY4+1 -> 45896 | QA4: =PZ4+1 -> 45897 | QB4: =QA4+1 -> 45898 | QC4: =QB4+3 -> 45901 | QD4: =QC4+1 -> 45902 | QE4: =QD4+1 -> 45903 | QF4: =QE4+1 -> 45904 | QG4: =QF4+1 -> 45905 | QH4: =QG4+3 -> 45908 | QI4: =QH4+1 -> 45909 | QJ4: =QI4+1 -> 45910 | QK4: =QJ4+1 -> 45911 | QL4: =QK4+1 -> 45912 | QM4: =QL4+3 -> 45915 | QN4: =QM4+1 -> 45916 | QO4: =QN4+1 -> 45917 | QP4: =QO4+1 -> 45918 | QQ4: =QP4+1 -> 45919 | QR4: =QQ4+3 -> 45922 | QS4: =QR4+1 -> 45923 | QT4: =QS4+1 -> 45924 | QU4: =QT4+1 -> 45925 | QV4: =QU4+1 -> 45926 | QW4: =QV4+3 -> 45929 | QX4: =QW4+1 -> 45930 | QY4: =QX4+1 -> 45931 | QZ4: =QY4+1 -> 45932 | RA4: =QZ4+1 -> 45933 | RB4: =RA4+3 -> 45936 | RC4: =RB4+1 -> 45937 | RD4: =RC4+1 -> 45938 | RE4: =RD4+1 -> 45939 | RF4: =RE4+1 -> 45940 | RG4: =RF4+3 -> 45943 | RH4: =RG4+1 -> 45944 | RI4: =RH4+1 -> 45945 | RJ4: =RI4+1 -> 45946 | RK4: =RJ4+1 -> 45947 | RL4: =RK4+3 -> 45950 | RM4: =RL4+1 -> 45951 | RN4: =RM4+1 -> 45952 | RO4: =RN4+1 -> 45953 | RP4: =RO4+1 -> 45954 | RQ4: =RP4+3 -> 45957 | RR4: =RQ4+1 -> 45958 | RS4: =RR4+1 -> 45959 | RT4: =RS4+1 -> 45960 | RU4: =RT4+1 -> 45961 | RV4: =RU4+3 -> 45964 | RW4: =RV4+1 -> 45965 | RX4: =RW4+1 -> 45966 | RY4: =RX4+1 -> 45967 | RZ4: =RY4+1 -> 45968 | SA4: =RZ4+3 -> 45971 | SB4: =SA4+1 -> 45972 | SC4: =SB4+1 -> 45973 | SD4: =SC4+1 -> 45974 | SE4: =SD4+1 -> 45975 | SF4: =SE4+3 -> 45978 | SG4: =SF4+1 -> 45979 | SH4: =SG4+1 -> 45980 | SI4: =SH4+1 -> 45981 | SJ4: =SI4+1 -> 45982 | SK4: =SJ4+3 -> 45985 | SL4: =SK4+1 -> 45986 | SM4: =SL4+1 -> 45987 | SN4: =SM4+1 -> 45988 | SO4: =SN4+1 -> 45989 | SP4: =SO4+3 -> 45992 | SQ4: =SP4+1 -> 45993 | SR4: =SQ4+1 -> 45994 | SS4: =SR4+1 -> 45995 | ST4: =SS4+1 -> 45996 | SU4: =ST4+3 -> 45999 | SV4: =SU4+1 -> 46000 | SW4: =SV4+1 -> 46001 | SX4: =SW4+1 -> 46002 | SY4: =SX4+1 -> 46003 | SZ4: =SY4+3 -> 46006 | TA4: =SZ4+1 -> 46007 | TB4: =TA4+1 -> 46008 | TC4: =TB4+1 -> 46009 | TD4: =TC4+1 -> 46010 | TE4: =TD4+3 -> 46013 | TF4: =TE4+1 -> 46014 | TG4: =TF4+1 -> 46015 | TH4: =TG4+1 -> 46016 | TI4: =TH4+1 -> 46017
A5: 착수 | B5: 기획 | C5: 계약 | D5: 대상/더위버 | E5: 45614 | F5: 45632 | G5: =NETWORKDAYS.INTL(E5,F5,1,공휴일!$B$4:$B$15) -> 15 | H5: =IFERROR(MIN(1,(DATEDIF(E5,TODAY(),"d")+1)/(DATEDIF(E5,F5,"d")+1)),0) -> 1 | I5: 1
C6: 킥오프 | D6: 대상/더위버 | E6: 45631 | F6: 45631 | G6: =NETWORKDAYS.INTL(E6,F6,1,공휴일!$B$4:$B$15) -> 1 | H6: =IFERROR(MIN(1,(DATEDIF(E6,TODAY(),"d")+1)/(DATEDIF(E6,F6,"d")+1)),0) -> 1 | I6: 1
C7: 구축방향/요구사항정의 | D7: 대상/더위버 | E7: 45631 | F7: 45636 | G7: =NETWORKDAYS.INTL(E7,F7,1,공휴일!$B$4:$B$15) -> 4 | H7: =IFERROR(MIN(1,(DATEDIF(E7,TODAY(),"d")+1)/(DATEDIF(E7,F7,"d")+1)),0) -> 1 | I7: 1
C8: WBS수립 | D8: 더위버 | E8: 45625 | F8: 45636 | G8: =NETWORKDAYS.INTL(E8,F8,1,공휴일!$B$4:$B$15) -> 8 | H8: =IFERROR(MIN(1,(DATEDIF(E8,TODAY(),"d")+1)/(DATEDIF(E8,F8,"d")+1)),0) -> 1 | I8: 1
C9: IA설계 | D9: 더위버 | E9: 45625 | F9: 45638 | G9: =NETWORKDAYS.INTL(E9,F9,1,공휴일!$B$4:$B$15) -> 10 | H9: =IFERROR(MIN(1,(DATEDIF(E9,TODAY(),"d")+1)/(DATEDIF(E9,F9,"d")+1)),0) -> 1 | I9: 1
C10: 콘텐츠 수급 - About Us | D10: 대상 | E10: 45628 | F10: 45646 | G10: =NETWORKDAYS.INTL(E10,F10,1,공휴일!$B$4:$B$15) -> 15 | H10: =IFERROR(MIN(1,(DATEDIF(E10,TODAY(),"d")+1)/(DATEDIF(E10,F10,"d")+1)),0) -> 1 | I10: 1
C11: 콘텐츠 수급 - Brand | D11: 대상 | E11: 45628 | F11: 45762 | G11: =NETWORKDAYS.INTL(E11,F11,1,공휴일!$B$4:$B$15) -> 90 | H11: =IFERROR(MIN(1,(DATEDIF(E11,TODAY(),"d")+1)/(DATEDIF(E11,F11,"d")+1)),0) -> 1 | I11: 0.75
C12: 콘텐츠 수급 - R&D | D12: 대상 | E12: 45628 | F12: 45646 | G12: =NETWORKDAYS.INTL(E12,F12,1,공휴일!$B$4:$B$15) -> 15 | H12: =IFERROR(MIN(1,(DATEDIF(E12,TODAY(),"d")+1)/(DATEDIF(E12,F12,"d")+1)),0) -> 1 | I12: 1
C13: 콘텐츠 수급 - Media | D13: 대상 | E13: 45628 | F13: 45646 | G13: =NETWORKDAYS.INTL(E13,F13,1,공휴일!$B$4:$B$15) -> 15 | H13: =IFERROR(MIN(1,(DATEDIF(E13,TODAY(),"d")+1)/(DATEDIF(E13,F13,"d")+1)),0) -> 1 | I13: 1
C14: 콘텐츠 수급 - Support | D14: 대상 | E14: 45628 | F14: 45716 | G14: =NETWORKDAYS.INTL(E14,F14,1,공휴일!$B$4:$B$15) -> 59 | H14: =IFERROR(MIN(1,(DATEDIF(E14,TODAY(),"d")+1)/(DATEDIF(E14,F14,"d")+1)),0) -> 1 | I14: 0.4
C15: 콘텐츠 수급- 기타 | D15: 대상 | E15: 45628 | F15: 45646 | G15: =NETWORKDAYS.INTL(E15,F15,1,공휴일!$B$4:$B$15) -> 15 | H15: =IFERROR(MIN(1,(DATEDIF(E15,TODAY(),"d")+1)/(DATEDIF(E15,F15,"d")+1)),0) -> 1 | I15: 0.9
B16: 개발 | C16: 서버 환경 확인 및 설정 협의 | D16: 대상/더위버 | E16: 45635 | F16: 45646 | G16: =NETWORKDAYS.INTL(E16,F16,1,공휴일!$B$4:$B$15) -> 10 | H16: =IFERROR(MIN(1,(DATEDIF(E16,TODAY(),"d")+1)/(DATEDIF(E16,F16,"d")+1)),0) -> 1 | I16: 1
C17: 내부 개발 환경 세팅 | D17: 더위버 | E17: 45649 | F17: 45660 | G17: =NETWORKDAYS.INTL(E17,F17,1,공휴일!$B$4:$B$15) -> 8 | H17: =IFERROR(MIN(1,(DATEDIF(E17,TODAY(),"d")+1)/(DATEDIF(E17,F17,"d")+1)),0) -> 1 | I17: 1
A18: Admin | B18: 기획 | C18: 관리자 기능 정의 | D18: 더위버 | E18: 45649 | F18: 45667 | G18: =NETWORKDAYS.INTL(E18,F18,1,공휴일!$B$4:$B$15) -> 13 | H18: =IFERROR(MIN(1,(DATEDIF(E18,TODAY(),"d")+1)/(DATEDIF(E18,F18,"d")+1)),0) -> 1 | I18: 0.9
C19: 화면설계 | D19: 더위버 | E19: 45656 | F19: 45681 | G19: =NETWORKDAYS.INTL(E19,F19,1,공휴일!$B$4:$B$15) -> 19 | H19: =IFERROR(MIN(1,(DATEDIF(E19,TODAY(),"d")+1)/(DATEDIF(E19,F19,"d")+1)),0) -> 1 | I19: 0.8
B20: 개발 | C20: 설계/협의 | D20: 더위버 | E20: 45663 | F20: 45667 | G20: =NETWORKDAYS.INTL(E20,F20,1,공휴일!$B$4:$B$15) -> 5 | H20: =IFERROR(MIN(1,(DATEDIF(E20,TODAY(),"d")+1)/(DATEDIF(E20,F20,"d")+1)),0) -> 1 | I20: 1
C21: 관리자 개발 | D21: 더위버 | E21: 45670 | F21: 45716 | G21: =NETWORKDAYS.INTL(E21,F21,1,공휴일!$B$4:$B$15) -> 31 | H21: =IFERROR(MIN(1,(DATEDIF(E21,TODAY(),"d")+1)/(DATEDIF(E21,F21,"d")+1)),0) -> 1 | I21: 0.19
A22: Front | B22: 기획 | C22: 화면설계 - 메인 | D22: 더위버 | E22: 45642 | F22: 45650 | G22: =NETWORKDAYS.INTL(E22,F22,1,공휴일!$B$4:$B$15) -> 7 | H22: =IFERROR(MIN(1,(DATEDIF(E22,TODAY(),"d")+1)/(DATEDIF(E22,F22,"d")+1)),0) -> 1 | I22: 0.95
A23: 국문 | C23: 화면설계 - About Us | D23: 더위버 | E23: 45635 | F23: 45666 | G23: =NETWORKDAYS.INTL(E23,F23,1,공휴일!$B$4:$B$15) -> 22 | H23: =IFERROR(MIN(1,(DATEDIF(E23,TODAY(),"d")+1)/(DATEDIF(E23,F23,"d")+1)),0) -> 1 | I23: 0.95
C24: 화면설계 - Brand | D24: 더위버 | E24: 45635 | F24: 45666 | G24: =NETWORKDAYS.INTL(E24,F24,1,공휴일!$B$4:$B$15) -> 22 | H24: =IFERROR(MIN(1,(DATEDIF(E24,TODAY(),"d")+1)/(DATEDIF(E24,F24,"d")+1)),0) -> 1 | I24: 0.95
C25: 화면설계 - R&D | D25: 더위버 | E25: 45635 | F25: 45666 | G25: =NETWORKDAYS.INTL(E25,F25,1,공휴일!$B$4:$B$15) -> 22 | H25: =IFERROR(MIN(1,(DATEDIF(E25,TODAY(),"d")+1)/(DATEDIF(E25,F25,"d")+1)),0) -> 1 | I25: 0.95
C26: 화면설계 - Media&IR | D26: 더위버 | E26: 45635 | F26: 45666 | G26: =NETWORKDAYS.INTL(E26,F26,1,공휴일!$B$4:$B$15) -> 22 | H26: =IFERROR(MIN(1,(DATEDIF(E26,TODAY(),"d")+1)/(DATEDIF(E26,F26,"d")+1)),0) -> 1 | I26: 0.95
C27: 화면설계 - Support | D27: 더위버 | E27: 45635 | F27: 45666 | G27: =NETWORKDAYS.INTL(E27,F27,1,공휴일!$B$4:$B$15) -> 22 | H27: =IFERROR(MIN(1,(DATEDIF(E27,TODAY(),"d")+1)/(DATEDIF(E27,F27,"d")+1)),0) -> 1 | I27: 0.9
C28: 화면설계 - 기타 | D28: 더위버 | E28: 45645 | F28: 45653 | G28: =NETWORKDAYS.INTL(E28,F28,1,공휴일!$B$4:$B$15) -> 6 | H28: =IFERROR(MIN(1,(DATEDIF(E28,TODAY(),"d")+1)/(DATEDIF(E28,F28,"d")+1)),0) -> 1 | I28: 1
C29: 콘텐츠 검수 및 심의 | D29: 대상 | E29: 45659 | F29: 45688 | G29: =NETWORKDAYS.INTL(E29,F29,1,공휴일!$B$4:$B$15) -> 18 | H29: =IFERROR(MIN(1,(DATEDIF(E29,TODAY(),"d")+1)/(DATEDIF(E29,F29,"d")+1)),0) -> 1 | I29: 0.67
B30: 디자인 | C30: 실행안 제작 - 메인 | D30: 더위버 | E30: 45635 | F30: 45642 | G30: =NETWORKDAYS.INTL(E30,F30,1,공휴일!$B$4:$B$15) -> 6 | H30: =IFERROR(MIN(1,(DATEDIF(E30,TODAY(),"d")+1)/(DATEDIF(E30,F30,"d")+1)),0) -> 1 | I30: 0.99
C31: 실행안 제작 - 서브 | D31: 더위버 | E31: 45635 | F31: 45642 | G31: =NETWORKDAYS.INTL(E31,F31,1,공휴일!$B$4:$B$15) -> 6 | H31: =IFERROR(MIN(1,(DATEDIF(E31,TODAY(),"d")+1)/(DATEDIF(E31,F31,"d")+1)),0) -> 1 | I31: 0.99
C32: 스타일 가이드 제작 | D32: 더위버 | E32: 45649 | F32: 45657 | G32: =NETWORKDAYS.INTL(E32,F32,1,공휴일!$B$4:$B$15) -> 6 | H32: =IFERROR(MIN(1,(DATEDIF(E32,TODAY(),"d")+1)/(DATEDIF(E32,F32,"d")+1)),0) -> 1 | I32: 0.98
C33: 페이지 디자인 - 메인 | D33: 더위버 | E33: 45691 | F33: 45695 | G33: =NETWORKDAYS.INTL(E33,F33,1,공휴일!$B$4:$B$15) -> 5 | H33: =IFERROR(MIN(1,(DATEDIF(E33,TODAY(),"d")+1)/(DATEDIF(E33,F33,"d")+1)),0) -> 1 | I33: 0
C34: 페이지 디자인 - About Us | D34: 더위버 | E34: 45666 | F34: 45688 | G34: =NETWORKDAYS.INTL(E34,F34,1,공휴일!$B$4:$B$15) -> 13 | H34: =IFERROR(MIN(1,(DATEDIF(E34,TODAY(),"d")+1)/(DATEDIF(E34,F34,"d")+1)),0) -> 1 | I34: 0.05
C35: 페이지 디자인 - Brand | D35: 더위버 | E35: 45672 | F35: 45695 | G35: =NETWORKDAYS.INTL(E35,F35,1,공휴일!$B$4:$B$15) -> 14 | H35: =IFERROR(MIN(1,(DATEDIF(E35,TODAY(),"d")+1)/(DATEDIF(E35,F35,"d")+1)),0) -> 1 | I35: 0.05
C36: 페이지 디자인 - R&D | D36: 더위버 | E36: 45684 | F36: 45695 | G36: =NETWORKDAYS.INTL(E36,F36,1,공휴일!$B$4:$B$15) -> 6 | H36: =IFERROR(MIN(1,(DATEDIF(E36,TODAY(),"d")+1)/(DATEDIF(E36,F36,"d")+1)),0) -> 1 | I36: 0.02
C37: 페이지 디자인 - Media&IR | D37: 더위버 | E37: 45666 | F37: 45674 | G37: =NETWORKDAYS.INTL(E37,F37,1,공휴일!$B$4:$B$15) -> 7 | H37: =IFERROR(MIN(1,(DATEDIF(E37,TODAY(),"d")+1)/(DATEDIF(E37,F37,"d")+1)),0) -> 1 | I37: 0.95
C38: 페이지 디자인 - Support | D38: 더위버 | E38: 45666 | F38: 45674 | G38: =NETWORKDAYS.INTL(E38,F38,1,공휴일!$B$4:$B$15) -> 7 | H38: =IFERROR(MIN(1,(DATEDIF(E38,TODAY(),"d")+1)/(DATEDIF(E38,F38,"d")+1)),0) -> 1 | I38: 0.95
C39: 페이지 디자인 - Support(나만의 솔루션) | D39: 더위버 | E39: 45677 | F39: 45688 | G39: =NETWORKDAYS.INTL(E39,F39,1,공휴일!$B$4:$B$15) -> 6 | H39: =IFERROR(MIN(1,(DATEDIF(E39,TODAY(),"d")+1)/(DATEDIF(E39,F39,"d")+1)),0) -> 1 | I39: 0
C40: 페이지 디자인 - 기타 | D40: 더위버 | E40: 45691 | F40: 45695 | G40: =NETWORKDAYS.INTL(E40,F40,1,공휴일!$B$4:$B$15) -> 5 | H40: =IFERROR(MIN(1,(DATEDIF(E40,TODAY(),"d")+1)/(DATEDIF(E40,F40,"d")+1)),0) -> 1 | I40: 0
...

Sheet V0.9
A1: 대상웰라이프_WBS
A2: ▥ Last update : | B2: 45728
A3: 구분 | C3: 세부 업무 항목 | D3: 담당 | E3: 시작일 | F3: 종료일 | G3: 기간 | H3: 날짜기준 진척률 | I3: 실제 진척률 | J3: 1월 | AF3: 2월 | AZ3: 3월 | BW3: 4월 | CQ3: 5월 | DN3: 6월 | EJ3: 7월 | FE3: 8월 | GB3: 9월 | GW3: 10월 | HS3: 11월 | IO3: 12월 | JJ3: 1월 | KF3: 2월 | KZ3: 3월 | LW3: 4월 | MQ3: 5월 | NN3: 6월 | OJ3: 7월 | PE3: 8월 | QB3: 9월 | QW3: 10월 | RS3: 11월 | SO3: 12월
J4: 45292 | K4: =J4+1 -> 45293 | L4: =K4+1 -> 45294 | M4: =L4+1 -> 45295 | N4: =M4+1 -> 45296 | O4: =N4+3 -> 45299 | P4: =O4+1 -> 45300 | Q4: =P4+1 -> 45301 | R4: =Q4+1 -> 45302 | S4: =R4+1 -> 45303 | T4: =S4+3 -> 45306 | U4: =T4+1 -> 45307 | V4: =U4+1 -> 45308 | W4: =V4+1 -> 45309 | X4: =W4+1 -> 45310 | Y4: =X4+3 -> 45313 | Z4: =Y4+1 -> 45314 | AA4: =Z4+1 -> 45315 | AB4: =AA4+1 -> 45316 | AC4: =AB4+1 -> 45317 | AD4: =AC4+3 -> 45320 | AE4: =AD4+1 -> 45321 | AF4: =AE4+1 -> 45322 | AG4: =AF4+1 -> 45323 | AH4: =AG4+1 -> 45324 | AI4: =AH4+3 -> 45327 | AJ4: =AI4+1 -> 45328 | AK4: =AJ4+1 -> 45329 | AL4: =AK4+1 -> 45330 | AM4: =AL4+1 -> 45331 | AN4: =AM4+3 -> 45334 | AO4: =AN4+1 -> 45335 | AP4: =AO4+1 -> 45336 | AQ4: =AP4+1 -> 45337 | AR4: =AQ4+1 -> 45338 | AS4: =AR4+3 -> 45341 | AT4: =AS4+1 -> 45342 | AU4: =AT4+1 -> 45343 | AV4: =AU4+1 -> 45344 | AW4: =AV4+1 -> 45345 | AX4: =AW4+3 -> 45348 | AY4: =AX4+1 -> 45349 | AZ4: =AY4+1 -> 45350 | BA4: =AZ4+1 -> 45351 | BB4: =BA4+1 -> 45352 | BC4: =BB4+3 -> 45355 | BD4: =BC4+1 -> 45356 | BE4: =BD4+1 -> 45357 | BF4: =BE4+1 -> 45358 | BG4: =BF4+1 -> 45359 | BH4: =BG4+3 -> 45362 | BI4: =BH4+1 -> 45363 | BJ4: =BI4+1 -> 45364 | BK4: =BJ4+1 -> 45365 | BL4: =BK4+1 -> 45366 | BM4: =BL4+3 -> 45369 | BN4: =BM4+1 -> 45370 | BO4: =BN4+1 -> 45371 | BP4: =BO4+1 -> 45372 | BQ4: =BP4+1 -> 45373 | BR4: =BQ4+3 -> 45376 | BS4: =BR4+1 -> 45377 | BT4: =BS4+1 -> 45378 | BU4: =BT4+1 -> 45379 | BV4: =BU4+1 -> 45380 | BW4: =BV4+3 -> 45383 | BX4: =BW4+1 -> 45384 | BY4: =BX4+1 -> 45385 | BZ4: =BY4+1 -> 45386 | CA4: =BZ4+1 -> 45387 | CB4: =CA4+3 -> 45390 | CC4: =CB4+1 -> 45391 | CD4: =CC4+1 -> 45392 | CE4: =CD4+1 -> 45393 | CF4: =CE4+1 -> 45394 | CG4: =CF4+3 -> 45397 | CH4: =CG4+1 -> 45398 | CI4: =CH4+1 -> 45399 | CJ4: =CI4+1 -> 45400 | CK4: =CJ4+1 -> 45401 | CL4: =CK4+3 -> 45404 | CM4: =CL4+1 -> 45405 | CN4: =CM4+1 -> 45406 | CO4: =CN4+1 -> 45407 | CP4: =CO4+1 -> 45408 | CQ4: =CP4+3 -> 45411 | CR4: =CQ4+1 -> 45412 | CS4: =CR4+1 -> 45413 | CT4: =CS4+1 -> 45414 | CU4: =CT4+1 -> 45415 | CV4: =CU4+3 -> 45418 | CW4: =CV4+1 -> 45419 | CX4: =CW4+1 -> 45420 | CY4: =CX4+1 -> 45421 | CZ4: =CY4+1 -> 45422 | DA4: =CZ4+3 -> 45425 | DB4: =DA4+1 -> 45426 | DC4: =DB4+1 -> 45427 | DD4: =DC4+1 -> 45428 | DE4: =DD4+1 -> 45429 | DF4: =DE4+3 -> 45432 | DG4: =DF4+1 -> 45433 | DH4: =DG4+1 -> 45434 | DI4: =DH4+1 -> 45435 | DJ4: =DI4+1 -> 45436 | DK4: =DJ4+3 -> 45439 | DL4: =DK4+1 -> 45440 | DM4: =DL4+1 -> 45441 | DN4: =DM4+1 -> 45442 | DO4: =DN4+1 -> 45443 | DP4: =DO4+3 -> 45446 | DQ4: =DP4+1 -> 45447 | DR4: =DQ4+1 -> 45448 | DS4: =DR4+1 -> 45449 | DT4: =DS4+1 -> 45450 | DU4: =DT4+3 -> 45453 | DV4: =DU4+1 -> 45454 | DW4: =DV4+1 -> 45455 | DX4: =DW4+1 -> 45456 | DY4: =DX4+1 -> 45457 | DZ4: =DY4+3 -> 45460 | EA4: =DZ4+1 -> 45461 | EB4: =EA4+1 -> 45462 | EC4: =EB4+1 -> 45463 | ED4: =EC4+1 -> 45464 | EE4: =ED4+3 -> 45467 | EF4: =EE4+1 -> 45468 | EG4: =EF4+1 -> 45469 | EH4: =EG4+1 -> 45470 | EI4: =EH4+1 -> 45471 | EJ4: =EI4+3 -> 45474 | EK4: =EJ4+1 -> 45475 | EL4: =EK4+1 -> 45476 | EM4: =EL4+1 -> 45477 | EN4: =EM4+1 -> 45478 | EO4: =EN4+3 -> 45481 | EP4: =EO4+1 -> 45482 | EQ4: =EP4+1 -> 45483 | ER4: =EQ4+1 -> 45484 | ES4: =ER4+1 -> 45485 | ET4: =ES4+3 -> 45488 | EU4: =ET4+1 -> 45489 | EV4: =EU4+1 -> 45490 | EW4: =EV4+1 -> 45491 | EX4: =EW4+1 -> 45492 | EY4: =EX4+3 -> 45495 | EZ4: =EY4+1 -> 45496 | FA4: =EZ4+1 -> 45497 | FB4: =FA4+1 -> 45498 | FC4: =FB4+1 -> 45499 | FD4: =FC4+3 -> 45502 | FE4: =FD4+1 -> 45503 | FF4: =FE4+1 -> 45504 | FG4: =FF4+1 -> 45505 | FH4: =FG4+1 -> 45506 | FI4: =FH4+3 -> 45509 | FJ4: =FI4+1 -> 45510 | FK4: =FJ4+1 -> 45511 | FL4: =FK4+1 -> 45512 | FM4: =FL4+1 -> 45513 | FN4: =FM4+3 -> 45516 | FO4: =FN4+1 -> 45517 | FP4: =FO4+1 -> 45518 | FQ4: =FP4+1 -> 45519 | FR4: =FQ4+1 -> 45520 | FS4: =FR4+3 -> 45523 | FT4: =FS4+1 -> 45524 | FU4: =FT4+1 -> 45525 | FV4: =FU4+1 -> 45526 | FW4: =FV4+1 -> 45527 | FX4: =FW4+3 -> 45530 | FY4: =FX4+1 -> 45531 | FZ4: =FY4+1 -> 45532 | GA4: =FZ4+1 -> 45533 | GB4: =GA4+1 -> 45534 | GC4: =GB4+3 -> 45537 | GD4: =GC4+1 -> 45538 | GE4: =GD4+1 -> 45539 | GF4: =GE4+1 -> 45540 | GG4: =GF4+1 -> 45541 | GH4: =GG4+3 -> 45544 | GI4: =GH4+1 -> 45545 | GJ4: =GI4+1 -> 45546 | GK4: =GJ4+1 -> 45547 | GL4: =GK4+1 -> 45548 | GM4: =GL4+3 -> 45551 | GN4: =GM4+1 -> 45552 | GO4: =GN4+1 -> 45553 | GP4: =GO4+1 -> 45554 | GQ4: =GP4+1 -> 45555 | GR4: =GQ4+3 -> 45558 | GS4: =GR4+1 -> 45559 | GT4: =GS4+1 -> 45560 | GU4: =GT4+1 -> 45561 | GV4: =GU4+1 -> 45562 | GW4: =GV4+3 -> 45565 | GX4: =GW4+1 -> 45566 | GY4: =GX4+1 -> 45567 | GZ4: =GY4+1 -> 45568 | HA4: =GZ4+1 -> 45569 | HB4: =HA4+3 -> 45572 | HC4: =HB4+1 -> 45573 | HD4: =HC4+1 -> 45574 | HE4: =HD4+1 -> 45575 | HF4: =HE4+1 -> 45576 | HG4: =HF4+3 -> 45579 | HH4: =HG4+1 -> 45580 | HI4: =HH4+1 -> 45581 | HJ4: =HI4+1 -> 45582 | HK4: =HJ4+1 -> 45583 | HL4: =HK4+3 -> 45586 | HM4: =HL4+1 -> 45587 | HN4: =HM4+1 -> 45588 | HO4: =HN4+1 -> 45589 | HP4: =HO4+1 -> 45590 | HQ4: =HP4+3 -> 45593 | HR4: =HQ4+1 -> 45594 | HS4: =HR4+1 -> 45595 | HT4: =HS4+1 -> 45596 | HU4: =HT4+1 -> 45597 | HV4: =HU4+3 -> 45600 | HW4: =HV4+1 -> 45601 | HX4: =HW4+1 -> 45602 | HY4: =HX4+1 -> 45603 | HZ4: =HY4+1 -> 45604 | IA4: =HZ4+3 -> 45607 | IB4: =IA4+1 -> 45608 | IC4: =IB4+1 -> 45609 | ID4: =IC4+1 -> 45610 | IE4: =ID4+1 -> 45611 | IF4: =IE4+3 -> 45614 | IG4: =IF4+1 -> 45615 | IH4: =IG4+1 -> 45616 | II4: =IH4+1 -> 45617 | IJ4: =II4+1 -> 45618 | IK4: =IJ4+3 -> 45621 | IL4: =IK4+1 -> 45622 | IM4: =IL4+1 -> 45623 | IN4: =IM4+1 -> 45624 | IO4: =IN4+1 -> 45625 | IP4: =IO4+3 -> 45628 | IQ4: =IP4+1 -> 45629 | IR4: =IQ4+1 -> 45630 | IS4: =IR4+1 -> 45631 | IT4: =IS4+1 -> 45632 | IU4: =IT4+3 -> 45635 | IV4: =IU4+1 -> 45636 | IW4: =IV4+1 -> 45637 | IX4: =IW4+1 -> 45638 | IY4: =IX4+1 -> 45639 | IZ4: =IY4+3 -> 45642 | JA4: =IZ4+1 -> 45643 | JB4: =JA4+1 -> 45644 | JC4: =JB4+1 -> 45645 | JD4: =JC4+1 -> 45646 | JE4: =JD4+3 -> 45649 | JF4: =JE4+1 -> 45650 | JG4: =JF4+1 -> 45651 | JH4: =JG4+1 -> 45652 | JI4: =JH4+1 -> 45653 | JJ4: =JI4+3 -> 45656 | JK4: =JJ4+1 -> 45657 | JL4: =JK4+1 -> 45658 | JM4: =JL4+1 -> 45659 | JN4: =JM4+1 -> 45660 | JO4: =JN4+3 -> 45663 | JP4: =JO4+1 -> 45664 | JQ4: =JP4+1 -> 45665 | JR4: =JQ4+1 -> 45666 | JS4: =JR4+1 -> 45667 | JT4: =JS4+3 -> 45670 | JU4: =JT4+1 -> 45671 | JV4: =JU4+1 -> 45672 | JW4: =JV4+1 -> 45673 | JX4: =JW4+1 -> 45674 | JY4: =JX4+3 -> 45677 | JZ4: =JY4+1 -> 45678 | KA4: =JZ4+1 -> 45679 | KB4: =KA4+1 -> 45680 | KC4: =KB4+1 -> 45681 | KD4: =KC4+3 -> 45684 | KE4: =KD4+1 -> 45685 | KF4: =KE4+1 -> 45686 | KG4: =KF4+1 -> 45687 | KH4: =KG4+1 -> 45688 | KI4: =KH4+3 -> 45691 | KJ4: =KI4+1 -> 45692 | KK4: =KJ4+1 -> 45693 | KL4: =KK4+1 -> 45694 | KM4: =KL4+1 -> 45695 | KN4: =KM4+3 -> 45698 | KO4: =KN4+1 -> 45699 | KP4: =KO4+1 -> 45700 | KQ4: =KP4+1 -> 45701 | KR4: =KQ4+1 -> 45702 | KS4: =KR4+3 -> 45705 | KT4: =KS4+1 -> 45706 | KU4: =KT4+1 -> 45707 | KV4: =KU4+1 -> 45708 | KW4: =KV4+1 -> 45709 | KX4: =KW4+3 -> 45712 | KY4: =KX4+1 -> 45713 | KZ4: =KY4+1 -> 45714 | LA4: =KZ4+1 -> 45715 | LB4: =LA4+1 -> 45716 | LC4: =LB4+3 -> 45719 | LD4: =LC4+1 -> 45720 | LE4: =LD4+1 -> 45721 | LF4: =LE4+1 -> 45722 | LG4: =LF4+1 -> 45723 | LH4: =LG4+3 -> 45726 | LI4: =LH4+1 -> 45727 | LJ4: =LI4+1 -> 45728 | LK4: =LJ4+1 -> 45729 | LL4: =LK4+1 -> 45730 | LM4: =LL4+3 -> 45733 | LN4: =LM4+1 -> 45734 | LO4: =LN4+1 -> 45735 | LP4: =LO4+1 -> 45736 | LQ4: =LP4+1 -> 45737 | LR4: =LQ4+3 -> 45740 | LS4: =LR4+1 -> 45741 | LT4: =LS4+1 -> 45742 | LU4: =LT4+1 -> 45743 | LV4: =LU4+1 -> 45744 | LW4: =LV4+3 -> 45747 | LX4: =LW4+1 -> 45748 | LY4: =LX4+1 -> 45749 | LZ4: =LY4+1 -> 45750 | MA4: =LZ4+1 -> 45751 | MB4: =MA4+3 -> 45754 | MC4: =MB4+1 -> 45755 | MD4: =MC4+1 -> 45756 | ME4: =MD4+1 -> 45757 | MF4: =ME4+1 -> 45758 | MG4: =MF4+3 -> 45761 | MH4: =MG4+1 -> 45762 | MI4: =MH4+1 -> 45763 | MJ4: =MI4+1 -> 45764 | MK4: =MJ4+1 -> 45765 | ML4: =MK4+3 -> 45768 | MM4: =ML4+1 -> 45769 | MN4: =MM4+1 -> 45770 | MO4: =MN4+1 -> 45771 | MP4: =MO4+1 -> 45772 | MQ4: =MP4+3 -> 45775 | MR4: =MQ4+1 -> 45776 | MS4: =MR4+1 -> 45777 | MT4: =MS4+1 -> 45778 | MU4: =MT4+1 -> 45779 | MV4: =MU4+3 -> 45782 | MW4: =MV4+1 -> 45783 | MX4: =MW4+1 -> 45784 | MY4: =MX4+1 -> 45785 | MZ4: =MY4+1 -> 45786 | NA4: =MZ4+3 -> 45789 | NB4: =NA4+1 -> 45790 | NC4: =NB4+1 -> 45791 | ND4: =NC4+1 -> 45792 | NE4: =ND4+1 -> 45793 | NF4: =NE4+3 -> 45796 | NG4: =NF4+1 -> 45797 | NH4: =NG4+1 -> 45798 | NI4: =NH4+1 -> 45799 | NJ4: =NI4+1 -> 45800 | NK4: =NJ4+3 -> 45803 | NL4: =NK4+1 -> 45804 | NM4: =NL4+1 -> 45805 | NN4: =NM4+1 -> 45806 | NO4: =NN4+1 -> 45807 | NP4: =NO4+3 -> 45810 | NQ4: =NP4+1 -> 45811 | NR4: =NQ4+1 -> 45812 | NS4: =NR4+1 -> 45813 | NT4: =NS4+1 -> 45814 | NU4: =NT4+3 -> 45817 | NV4: =NU4+1 -> 45818 | NW4: =NV4+1 -> 45819 | NX4: =NW4+1 -> 45820 | NY4: =NX4+1 -> 45821 | NZ4: =NY4+3 -> 45824 | OA4: =NZ4+1 -> 45825 | OB4: =OA4+1 -> 45826 | OC4: =OB4+1 -> 45827 | OD4: =OC4+1 -> 45828 | OE4: =OD4+3 -> 45831 | OF4: =OE4+1 -> 45832 | OG4: =OF4+1 -> 45833 | OH4: =OG4+1 -> 45834 | OI4: =OH4+1 -> 45835 | OJ4: =OI4+3 -> 45838 | OK4: =OJ4+1 -> 45839 | OL4: =OK4+1 -> 45840 | OM4: =OL4+1 -> 45841 | ON4: =OM4+1 -> 45842 | OO4: =ON4+3 -> 45845 | OP4: =OO4+1 -> 45846 | OQ4: =OP4+1 -> 45847 | OR4: =OQ4+1 -> 45848 | OS4: =OR4+1 -> 45849 | OT4: =OS4+3 -> 45852 | OU4: =OT4+1 -> 45853 | OV4: =OU4+1 -> 45854 | OW4: =OV4+1 -> 45855 | OX4: =OW4+1 -> 45856 | OY4: =OX4+3 -> 45859 | OZ4: =OY4+1 -> 45860 | PA4: =OZ4+1 -> 45861 | PB4: =PA4+1 -> 45862 | PC4: =PB4+1 -> 45863 | PD4: =PC4+3 -> 45866 | PE4: =PD4+1 -> 45867 | PF4: =PE4+1 -> 45868 | PG4: =PF4+1 -> 45869 | PH4: =PG4+1 -> 45870 | PI4: =PH4+3 -> 45873 | PJ4: =PI4+1 -> 45874 | PK4: =PJ4+1 -> 45875 | PL4: =PK4+1 -> 45876 | PM4: =PL4+1 -> 45877 | PN4: =PM4+3 -> 45880 | PO4: =PN4+1 -> 45881 | PP4: =PO4+1 -> 45882 | PQ4: =PP4+1 -> 45883 | PR4: =PQ4+1 -> 45884 | PS4: =PR4+3 -> 45887 | PT4: =PS4+1 -> 45888 | PU4: =PT4+1 -> 45889 | PV4: =PU4+1 -> 45890 | PW4: =PV4+1 -> 45891 | PX4: =PW4+3 -> 45894 | PY4: =PX4+1 -> 45895 | PZ4: =PY4+1 -> 45896 | QA4: =PZ4+1 -> 45897 | QB4: =QA4+1 -> 45898 | QC4: =QB4+3 -> 45901 | QD4: =QC4+1 -> 45902 | QE4: =QD4+1 -> 45903 | QF4: =QE4+1 -> 45904 | QG4: =QF4+1 -> 45905 | QH4: =QG4+3 -> 45908 | QI4: =QH4+1 -> 45909 | QJ4: =QI4+1 -> 45910 | QK4: =QJ4+1 -> 45911 | QL4: =QK4+1 -> 45912 | QM4: =QL4+3 -> 45915 | QN4: =QM4+1 -> 45916 | QO4: =QN4+1 -> 45917 | QP4: =QO4+1 -> 45918 | QQ4: =QP4+1 -> 45919 | QR4: =QQ4+3 -> 45922 | QS4: =QR4+1 -> 45923 | QT4: =QS4+1 -> 45924 | QU4: =QT4+1 -> 45925 | QV4: =QU4+1 -> 45926 | QW4: =QV4+3 -> 45929 | QX4: =QW4+1 -> 45930 | QY4: =QX4+1 -> 45931 | QZ4: =QY4+1 -> 45932 | RA4: =QZ4+1 -> 45933 | RB4: =RA4+3 -> 45936 | RC4: =RB4+1 -> 45937 | RD4: =RC4+1 -> 45938 | RE4: =RD4+1 -> 45939 | RF4: =RE4+1 -> 45940 | RG4: =RF4+3 -> 45943 | RH4: =RG4+1 -> 45944 | RI4: =RH4+1 -> 45945 | RJ4: =RI4+1 -> 45946 | RK4: =RJ4+1 -> 45947 | RL4: =RK4+3 -> 45950 | RM4: =RL4+1 -> 45951 | RN4: =RM4+1 -> 45952 | RO4: =RN4+1 -> 45953 | RP4: =RO4+1 -> 45954 | RQ4: =RP4+3 -> 45957 | RR4: =RQ4+1 -> 45958 | RS4: =RR4+1 -> 45959 | RT4: =RS4+1 -> 45960 | RU4: =RT4+1 -> 45961 | RV4: =RU4+3 -> 45964 | RW4: =RV4+1 -> 45965 | RX4: =RW4+1 -> 45966 | RY4: =RX4+1 -> 45967 | RZ4: =RY4+1 -> 45968 | SA4: =RZ4+3 -> 45971 | SB4: =SA4+1 -> 45972 | SC4: =SB4+1 -> 45973 | SD4: =SC4+1 -> 45974 | SE4: =SD4+1 -> 45975 | SF4: =SE4+3 -> 45978 | SG4: =SF4+1 -> 45979 | SH4: =SG4+1 -> 45980 | SI4: =SH4+1 -> 45981 | SJ4: =SI4+1 -> 45982 | SK4: =SJ4+3 -> 45985 | SL4: =SK4+1 -> 45986 | SM4: =SL4+1 -> 45987 | SN4: =SM4+1 -> 45988 | SO4: =SN4+1 -> 45989 | SP4: =SO4+3 -> 45992 | SQ4: =SP4+1 -> 45993 | SR4: =SQ4+1 -> 45994 | SS4: =SR4+1 -> 45995 | ST4: =SS4+1 -> 45996 | SU4: =ST4+3 -> 45999 | SV4: =SU4+1 -> 46000 | SW4: =SV4+1 -> 46001 | SX4: =SW4+1 -> 46002 | SY4: =SX4+1 -> 46003 | SZ4: =SY4+3 -> 46006 | TA4: =SZ4+1 -> 46007 | TB4: =TA4+1 -> 46008 | TC4: =TB4+1 -> 46009 | TD4: =TC4+1 -> 46010 | TE4: =TD4+3 -> 46013 | TF4: =TE4+1 -> 46014 | TG4: =TF4+1 -> 46015 | TH4: =TG4+1 -> 46016 | TI4: =TH4+1 -> 46017
A5: 착수 | B5: 기획 | C5: 계약 | D5: 대상/더위버 | E5: 45614 | F5: 45632 | G5: =NETWORKDAYS.INTL(E5,F5,1,공휴일!$B$4:$B$15) -> 15 | H5: =IFERROR(MIN(1,(DATEDIF(E5,TODAY(),"d")+1)/(DATEDIF(E5,F5,"d")+1)),0) -> 1 | I5: 1
C6: 킥오프 | D6: 대상/더위버 | E6: 45631 | F6: 45631 | G6: =NETWORKDAYS.INTL(E6,F6,1,공휴일!$B$4:$B$15) -> 1 | H6: =IFERROR(MIN(1,(DATEDIF(E6,TODAY(),"d")+1)/(DATEDIF(E6,F6,"d")+1)),0) -> 1 | I6: 1
C7: 구축방향/요구사항정의 | D7: 대상/더위버 | E7: 45631 | F7: 45636 | G7: =NETWORKDAYS.INTL(E7,F7,1,공휴일!$B$4:$B$15) -> 4 | H7: =IFERROR(MIN(1,(DATEDIF(E7,TODAY(),"d")+1)/(DATEDIF(E7,F7,"d")+1)),0) -> 1 | I7: 1
C8: WBS수립 | D8: 더위버 | E8: 45625 | F8: 45636 | G8: =NETWORKDAYS.INTL(E8,F8,1,공휴일!$B$4:$B$15) -> 8 | H8: =IFERROR(MIN(1,(DATEDIF(E8,TODAY(),"d")+1)/(DATEDIF(E8,F8,"d")+1)),0) -> 1 | I8: 1
C9: IA설계 | D9: 더위버 | E9: 45625 | F9: 45638 | G9: =NETWORKDAYS.INTL(E9,F9,1,공휴일!$B$4:$B$15) -> 10 | H9: =IFERROR(MIN(1,(DATEDIF(E9,TODAY(),"d")+1)/(DATEDIF(E9,F9,"d")+1)),0) -> 1 | I9: 1
C10: 콘텐츠 수급 - About Us | D10: 대상 | E10: 45628 | F10: 45646 | G10: =NETWORKDAYS.INTL(E10,F10,1,공휴일!$B$4:$B$15) -> 15 | H10: =IFERROR(MIN(1,(DATEDIF(E10,TODAY(),"d")+1)/(DATEDIF(E10,F10,"d")+1)),0) -> 1 | I10: 1
C11: 콘텐츠 수급 - Brand | D11: 대상 | E11: 45628 | F11: 45737 | G11: =NETWORKDAYS.INTL(E11,F11,1,공휴일!$B$4:$B$15) -> 73 | H11: =IFERROR(MIN(1,(DATEDIF(E11,TODAY(),"d")+1)/(DATEDIF(E11,F11,"d")+1)),0) -> 1 | I11: 1
C12: 콘텐츠 수급 - R&D | D12: 대상 | E12: 45628 | F12: 45646 | G12: =NETWORKDAYS.INTL(E12,F12,1,공휴일!$B$4:$B$15) -> 15 | H12: =IFERROR(MIN(1,(DATEDIF(E12,TODAY(),"d")+1)/(DATEDIF(E12,F12,"d")+1)),0) -> 1 | I12: 1
C13: 콘텐츠 수급 - Media | D13: 대상 | E13: 45628 | F13: 45646 | G13: =NETWORKDAYS.INTL(E13,F13,1,공휴일!$B$4:$B$15) -> 15 | H13: =IFERROR(MIN(1,(DATEDIF(E13,TODAY(),"d")+1)/(DATEDIF(E13,F13,"d")+1)),0) -> 1 | I13: 1
C14: 콘텐츠 수급 - Support | D14: 대상 | E14: 45628 | F14: 45716 | G14: =NETWORKDAYS.INTL(E14,F14,1,공휴일!$B$4:$B$15) -> 59 | H14: =IFERROR(MIN(1,(DATEDIF(E14,TODAY(),"d")+1)/(DATEDIF(E14,F14,"d")+1)),0) -> 1 | I14: 1
C15: 콘텐츠 수급- 기타 | D15: 대상 | E15: 45628 | F15: 45646 | G15: =NETWORKDAYS.INTL(E15,F15,1,공휴일!$B$4:$B$15) -> 15 | H15: =IFERROR(MIN(1,(DATEDIF(E15,TODAY(),"d")+1)/(DATEDIF(E15,F15,"d")+1)),0) -> 1 | I15: 0.99
B16: 개발 | C16: 서버 환경 확인 및 설정 협의 | D16: 대상/더위버 | E16: 45635 | F16: 45646 | G16: =NETWORKDAYS.INTL(E16,F16,1,공휴일!$B$4:$B$15) -> 10 | H16: =IFERROR(MIN(1,(DATEDIF(E16,TODAY(),"d")+1)/(DATEDIF(E16,F16,"d")+1)),0) -> 1 | I16: 1
C17: 내부 개발 환경 세팅 | D17: 더위버 | E17: 45649 | F17: 45660 | G17: =NETWORKDAYS.INTL(E17,F17,1,공휴일!$B$4:$B$15) -> 8 | H17: =IFERROR(MIN(1,(DATEDIF(E17,TODAY(),"d")+1)/(DATEDIF(E17,F17,"d")+1)),0) -> 1 | I17: 1
A18: Admin | B18: 기획 | C18: 관리자 기능 정의 | D18: 더위버 | E18: 45649 | F18: 45667 | G18: =NETWORKDAYS.INTL(E18,F18,1,공휴일!$B$4:$B$15) -> 13 | H18: =IFERROR(MIN(1,(DATEDIF(E18,TODAY(),"d")+1)/(DATEDIF(E18,F18,"d")+1)),0) -> 1 | I18: 1
C19: 화면설계 | D19: 더위버 | E19: 45656 | F19: 45681 | G19: =NETWORKDAYS.INTL(E19,F19,1,공휴일!$B$4:$B$15) -> 19 | H19: =IFERROR(MIN(1,(DATEDIF(E19,TODAY(),"d")+1)/(DATEDIF(E19,F19,"d")+1)),0) -> 1 | I19: 1
B20: 개발 | C20: 설계/협의 | D20: 더위버 | E20: 45663 | F20: 45667 | G20: =NETWORKDAYS.INTL(E20,F20,1,공휴일!$B$4:$B$15) -> 5 | H20: =IFERROR(MIN(1,(DATEDIF(E20,TODAY(),"d")+1)/(DATEDIF(E20,F20,"d")+1)),0) -> 1 | I20: 1
C21: 관리자 개발 | D21: 더위버 | E21: 45670 | F21: 45730 | G21: =NETWORKDAYS.INTL(E21,F21,1,공휴일!$B$4:$B$15) -> 40 | H21: =IFERROR(MIN(1,(DATEDIF(E21,TODAY(),"d")+1)/(DATEDIF(E21,F21,"d")+1)),0) -> 1 | I21: 0.95
A22: Front | B22: 기획 | C22: 화면설계 - 메인 | D22: 더위버 | E22: 45642 | F22: 45650 | G22: =NETWORKDAYS.INTL(E22,F22,1,공휴일!$B$4:$B$15) -> 7 | H22: =IFERROR(MIN(1,(DATEDIF(E22,TODAY(),"d")+1)/(DATEDIF(E22,F22,"d")+1)),0) -> 1 | I22: 1
A23: 국문 | C23: 화면설계 - About Us | D23: 더위버 | E23: 45635 | F23: 45666 | G23: =NETWORKDAYS.INTL(E23,F23,1,공휴일!$B$4:$B$15) -> 22 | H23: =IFERROR(MIN(1,(DATEDIF(E23,TODAY(),"d")+1)/(DATEDIF(E23,F23,"d")+1)),0) -> 1 | I23: 1
C24: 화면설계 - Brand | D24: 더위버 | E24: 45635 | F24: 45666 | G24: =NETWORKDAYS.INTL(E24,F24,1,공휴일!$B$4:$B$15) -> 22 | H24: =IFERROR(MIN(1,(DATEDIF(E24,TODAY(),"d")+1)/(DATEDIF(E24,F24,"d")+1)),0) -> 1 | I24: 1
C25: 화면설계 - R&D | D25: 더위버 | E25: 45635 | F25: 45666 | G25: =NETWORKDAYS.INTL(E25,F25,1,공휴일!$B$4:$B$15) -> 22 | H25: =IFERROR(MIN(1,(DATEDIF(E25,TODAY(),"d")+1)/(DATEDIF(E25,F25,"d")+1)),0) -> 1 | I25: 1
C26: 화면설계 - Media&IR | D26: 더위버 | E26: 45635 | F26: 45666 | G26: =NETWORKDAYS.INTL(E26,F26,1,공휴일!$B$4:$B$15) -> 22 | H26: =IFERROR(MIN(1,(DATEDIF(E26,TODAY(),"d")+1)/(DATEDIF(E26,F26,"d")+1)),0) -> 1 | I26: 1
C27: 화면설계 - Support | D27: 더위버 | E27: 45635 | F27: 45666 | G27: =NETWORKDAYS.INTL(E27,F27,1,공휴일!$B$4:$B$15) -> 22 | H27: =IFERROR(MIN(1,(DATEDIF(E27,TODAY(),"d")+1)/(DATEDIF(E27,F27,"d")+1)),0) -> 1 | I27: 1
C28: 화면설계 - 기타 | D28: 더위버 | E28: 45645 | F28: 45653 | G28: =NETWORKDAYS.INTL(E28,F28,1,공휴일!$B$4:$B$15) -> 6 | H28: =IFERROR(MIN(1,(DATEDIF(E28,TODAY(),"d")+1)/(DATEDIF(E28,F28,"d")+1)),0) -> 1 | I28: 1
C29: 콘텐츠 검수 및 심의 | D29: 대상 | E29: 45659 | F29: 45744 | G29: =NETWORKDAYS.INTL(E29,F29,1,공휴일!$B$4:$B$15) -> 57 | H29: =IFERROR(MIN(1,(DATEDIF(E29,TODAY(),"d")+1)/(DATEDIF(E29,F29,"d")+1)),0) -> 1 | I29: 0.95
B30: 디자인 | C30: 실행안 제작 - 메인 | D30: 더위버 | E30: 45635 | F30: 45679 | G30: =NETWORKDAYS.INTL(E30,F30,1,공휴일!$B$4:$B$15) -> 31 | H30: =IFERROR(MIN(1,(DATEDIF(E30,TODAY(),"d")+1)/(DATEDIF(E30,F30,"d")+1)),0) -> 1 | I30: 1
C31: 실행안 제작 - 서브 | D31: 더위버 | E31: 45635 | F31: 45679 | G31: =NETWORKDAYS.INTL(E31,F31,1,공휴일!$B$4:$B$15) -> 31 | H31: =IFERROR(MIN(1,(DATEDIF(E31,TODAY(),"d")+1)/(DATEDIF(E31,F31,"d")+1)),0) -> 1 | I31: 1
C32: 스타일 가이드 제작 | D32: 더위버 | E32: 45649 | F32: 45681 | G32: =NETWORKDAYS.INTL(E32,F32,1,공휴일!$B$4:$B$15) -> 23 | H32: =IFERROR(MIN(1,(DATEDIF(E32,TODAY(),"d")+1)/(DATEDIF(E32,F32,"d")+1)),0) -> 1 | I32: 1
C33: 페이지 디자인 - 메인 | D33: 더위버 | E33: 45705 | F33: 45709 | G33: =NETWORKDAYS.INTL(E33,F33,1,공휴일!$B$4:$B$15) -> 5 | H33: =IFERROR(MIN(1,(DATEDIF(E33,TODAY(),"d")+1)/(DATEDIF(E33,F33,"d")+1)),0) -> 1 | I33: 1
C34: 페이지 디자인 - About Us | D34: 더위버 | E34: 45677 | F34: 45716 | G34: =NETWORKDAYS.INTL(E34,F34,1,공휴일!$B$4:$B$15) -> 26 | H34: =IFERROR(MIN(1,(DATEDIF(E34,TODAY(),"d")+1)/(DATEDIF(E34,F34,"d")+1)),0) -> 1 | I34: 1
C35: 페이지 디자인 - Brand | D35: 더위버 | E35: 45677 | F35: 45713 | G35: =NETWORKDAYS.INTL(E35,F35,1,공휴일!$B$4:$B$15) -> 23 | H35: =IFERROR(MIN(1,(DATEDIF(E35,TODAY(),"d")+1)/(DATEDIF(E35,F35,"d")+1)),0) -> 1 | I35: 1
C36: 페이지 디자인 - R&D | D36: 더위버 | E36: 45705 | F36: 45716 | G36: =NETWORKDAYS.INTL(E36,F36,1,공휴일!$B$4:$B$15) -> 10 | H36: =IFERROR(MIN(1,(DATEDIF(E36,TODAY(),"d")+1)/(DATEDIF(E36,F36,"d")+1)),0) -> 1 | I36: 1
C37: 페이지 디자인 - Media&IR | D37: 더위버 | E37: 45666 | F37: 45679 | G37: =NETWORKDAYS.INTL(E37,F37,1,공휴일!$B$4:$B$15) -> 10 | H37: =IFERROR(MIN(1,(DATEDIF(E37,TODAY(),"d")+1)/(DATEDIF(E37,F37,"d")+1)),0) -> 1 | I37: 1
C38: 페이지 디자인 - Support | D38: 더위버 | E38: 45666 | F38: 45679 | G38: =NETWORKDAYS.INTL(E38,F38,1,공휴일!$B$4:$B$15) -> 10 | H38: =IFERROR(MIN(1,(DATEDIF(E38,TODAY(),"d")+1)/(DATEDIF(E38,F38,"d")+1)),0) -> 1 | I38: 1
C39: 페이지 디자인 - Support(Wellife Solution) | D39: 더위버 | E39: 45698 | F39: 45702 | G39: =NETWORKDAYS.INTL(E39,F39,1,공휴일!$B$4:$B$15) -> 5 | H39: =IFERROR(MIN(1,(DATEDIF(E39,TODAY(),"d")+1)/(DATEDIF(E39,F39,"d")+1)),0) -> 1 | I39: 1
C40: 페이지 디자인 - 기타 | D40: 더위버 | E40: 45726 | F40: 45728 | G40: =NETWORKDAYS.INTL(E40,F40,1,공휴일!$B$4:$B$15) -> 3 | H40: =IFERROR(MIN(1,(DATEDIF(E40,TODAY(),"d")+1)/(DATEDIF(E40,F40,"d")+1)),0) -> 1 | I40: 1
...

Sheet V0.8
A1: 대상웰라이프_WBS
A2: ▥ Last update : | B2: 45728
A3: 구분 | C3: 세부 업무 항목 | D3: 담당 | E3: 시작일 | F3: 종료일 | G3: 기간 | H3: 날짜기준 진척률 | I3: 실제 진척률 | J3: 1월 | AF3: 2월 | AZ3: 3월 | BW3: 4월 | CQ3: 5월 | DN3: 6월 | EJ3: 7월 | FE3: 8월 | GB3: 9월 | GW3: 10월 | HS3: 11월 | IO3: 12월 | JJ3: 1월 | KF3: 2월 | KZ3: 3월 | LW3: 4월 | MQ3: 5월 | NN3: 6월 | OJ3: 7월 | PE3: 8월 | QB3: 9월 | QW3: 10월 | RS3: 11월 | SO3: 12월
J4: 45292 | K4: =J4+1 -> 45293 | L4: =K4+1 -> 45294 | M4: =L4+1 -> 45295 | N4: =M4+1 -> 45296 | O4: =N4+3 -> 45299 | P4: =O4+1 -> 45300 | Q4: =P4+1 -> 45301 | R4: =Q4+1 -> 45302 | S4: =R4+1 -> 45303 | T4: =S4+3 -> 45306 | U4: =T4+1 -> 45307 | V4: =U4+1 -> 45308 | W4: =V4+1 -> 45309 | X4: =W4+1 -> 45310 | Y4: =X4+3 -> 45313 | Z4: =Y4+1 -> 45314 | AA4: =Z4+1 -> 45315 | AB4: =AA4+1 -> 45316 | AC4: =AB4+1 -> 45317 | AD4: =AC4+3 -> 45320 | AE4: =AD4+1 -> 45321 | AF4: =AE4+1 -> 45322 | AG4: =AF4+1 -> 45323 | AH4: =AG4+1 -> 45324 | AI4: =AH4+3 -> 45327 | AJ4: =AI4+1 -> 45328 | AK4: =AJ4+1 -> 45329 | AL4: =AK4+1 -> 45330 | AM4: =AL4+1 -> 45331 | AN4: =AM4+3 -> 45334 | AO4: =AN4+1 -> 45335 | AP4: =AO4+1 -> 45336 | AQ4: =AP4+1 -> 45337 | AR4: =AQ4+1 -> 45338 | AS4: =AR4+3 -> 45341 | AT4: =AS4+1 -> 45342 | AU4: =AT4+1 -> 45343 | AV4: =AU4+1 -> 45344 | AW4: =AV4+1 -> 45345 | AX4: =AW4+3 -> 45348 | AY4: =AX4+1 -> 45349 | AZ4: =AY4+1 -> 45350 | BA4: =AZ4+1 -> 45351 | BB4: =BA4+1 -> 45352 | BC4: =BB4+3 -> 45355 | BD4: =BC4+1 -> 45356 | BE4: =BD4+1 -> 45357 | BF4: =BE4+1 -> 45358 | BG4: =BF4+1 -> 45359 | BH4: =BG4+3 -> 45362 | BI4: =BH4+1 -> 45363 | BJ4: =BI4+1 -> 45364 | BK4: =BJ4+1 -> 45365 | BL4: =BK4+1 -> 45366 | BM4: =BL4+3 -> 45369 | BN4: =BM4+1 -> 45370 | BO4: =BN4+1 -> 45371 | BP4: =BO4+1 -> 45372 | BQ4: =BP4+1 -> 45373 | BR4: =BQ4+3 -> 45376 | BS4: =BR4+1 -> 45377 | BT4: =BS4+1 -> 45378 | BU4: =BT4+1 -> 45379 | BV4: =BU4+1 -> 45380 | BW4: =BV4+3 -> 45383 | BX4: =BW4+1 -> 45384 | BY4: =BX4+1 -> 45385 | BZ4: =BY4+1 -> 45386 | CA4: =BZ4+1 -> 45387 | CB4: =CA4+3 -> 45390 | CC4: =CB4+1 -> 45391 | CD4: =CC4+1 -> 45392 | CE4: =CD4+1 -> 45393 | CF4: =CE4+1 -> 45394 | CG4: =CF4+3 -> 45397 | CH4: =CG4+1 -> 45398 | CI4: =CH4+1 -> 45399 | CJ4: =CI4+1 -> 45400 | CK4: =CJ4+1 -> 45401 | CL4: =CK4+3 -> 45404 | CM4: =CL4+1 -> 45405 | CN4: =CM4+1 -> 45406 | CO4: =CN4+1 -> 45407 | CP4: =CO4+1 -> 45408 | CQ4: =CP4+3 -> 45411 | CR4: =CQ4+1 -> 45412 | CS4: =CR4+1 -> 45413 | CT4: =CS4+1 -> 45414 | CU4: =CT4+1 -> 45415 | CV4: =CU4+3 -> 45418 | CW4: =CV4+1 -> 45419 | CX4: =CW4+1 -> 45420 | CY4: =CX4+1 -> 45421 | CZ4: =CY4+1 -> 45422 | DA4: =CZ4+3 -> 45425 | DB4: =DA4+1 -> 45426 | DC4: =DB4+1 -> 45427 | DD4: =DC4+1 -> 45428 | DE4: =DD4+1 -> 45429 | DF4: =DE4+3 -> 45432 | DG4: =DF4+1 -> 45433 | DH4: =DG4+1 -> 45434 | DI4: =DH4+1 -> 45435 | DJ4: =DI4+1 -> 45436 | DK4: =DJ4+3 -> 45439 | DL4: =DK4+1 -> 45440 | DM4: =DL4+1 -> 45441 | DN4: =DM4+1 -> 45442 | DO4: =DN4+1 -> 45443 | DP4: =DO4+3 -> 45446 | DQ4: =DP4+1 -> 45447 | DR4: =DQ4+1 -> 45448 | DS4: =DR4+1 -> 45449 | DT4: =DS4+1 -> 45450 | DU4: =DT4+3 -> 45453 | DV4: =DU4+1 -> 45454 | DW4: =DV4+1 -> 45455 | DX4: =DW4+1 -> 45456 | DY4: =DX4+1 -> 45457 | DZ4: =DY4+3 -> 45460 | EA4: =DZ4+1 -> 45461 | EB4: =EA4+1 -> 45462 | EC4: =EB4+1 -> 45463 | ED4: =EC4+1 -> 45464 | EE4: =ED4+3 -> 45467 | EF4: =EE4+1 -> 45468 | EG4: =EF4+1 -> 45469 | EH4: =EG4+1 -> 45470 | EI4: =EH4+1 -> 45471 | EJ4: =EI4+3 -> 45474 | EK4: =EJ4+1 -> 45475 | EL4: =EK4+1 -> 45476 | EM4: =EL4+1 -> 45477 | EN4: =EM4+1 -> 45478 | EO4: =EN4+3 -> 45481 | EP4: =EO4+1 -> 45482 | EQ4: =EP4+1 -> 45483 | ER4: =EQ4+1 -> 45484 | ES4: =ER4+1 -> 45485 | ET4: =ES4+3 -> 45488 | EU4: =ET4+1 -> 45489 | EV4: =EU4+1 -> 45490 | EW4: =EV4+1 -> 45491 | EX4: =EW4+1 -> 45492 | EY4: =EX4+3 -> 45495 | EZ4: =EY4+1 -> 45496 | FA4: =EZ4+1 -> 45497 | FB4: =FA4+1 -> 45498 | FC4: =FB4+1 -> 45499 | FD4: =FC4+3 -> 45502 | FE4: =FD4+1 -> 45503 | FF4: =FE4+1 -> 45504 | FG4: =FF4+1 -> 45505 | FH4: =FG4+1 -> 45506 | FI4: =FH4+3 -> 45509 | FJ4: =FI4+1 -> 45510 | FK4: =FJ4+1 -> 45511 | FL4: =FK4+1 -> 45512 | FM4: =FL4+1 -> 45513 | FN4: =FM4+3 -> 45516 | FO4: =FN4+1 -> 45517 | FP4: =FO4+1 -> 45518 | FQ4: =FP4+1 -> 45519 | FR4: =FQ4+1 -> 45520 | FS4: =FR4+3 -> 45523 | FT4: =FS4+1 -> 45524 | FU4: =FT4+1 -> 45525 | FV4: =FU4+1 -> 45526 | FW4: =FV4+1 -> 45527 | FX4: =FW4+3 -> 45530 | FY4: =FX4+1 -> 45531 | FZ4: =FY4+1 -> 45532 | GA4: =FZ4+1 -> 45533 | GB4: =GA4+1 -> 45534 | GC4: =GB4+3 -> 45537 | GD4: =GC4+1 -> 45538 | GE4: =GD4+1 -> 45539 | GF4: =GE4+1 -> 45540 | GG4: =GF4+1 -> 45541 | GH4: =GG4+3 -> 45544 | GI4: =GH4+1 -> 45545 | GJ4: =GI4+1 -> 45546 | GK4: =GJ4+1 -> 45547 | GL4: =GK4+1 -> 45548 | GM4: =GL4+3 -> 45551 | GN4: =GM4+1 -> 45552 | GO4: =GN4+1 -> 45553 | GP4: =GO4+1 -> 45554 | GQ4: =GP4+1 -> 45555 | GR4: =GQ4+3 -> 45558 | GS4: =GR4+1 -> 45559 | GT4: =GS4+1 -> 45560 | GU4: =GT4+1 -> 45561 | GV4: =GU4+1 -> 45562 | GW4: =GV4+3 -> 45565 | GX4: =GW4+1 -> 45566 | GY4: =GX4+1 -> 45567 | GZ4: =GY4+1 -> 45568 | HA4: =GZ4+1 -> 45569 | HB4: =HA4+3 -> 45572 | HC4: =HB4+1 -> 45573 | HD4: =HC4+1 -> 45574 | HE4: =HD4+1 -> 45575 | HF4: =HE4+1 -> 45576 | HG4: =HF4+3 -> 45579 | HH4: =HG4+1 -> 45580 | HI4: =HH4+1 -> 45581 | HJ4: =HI4+1 -> 45582 | HK4: =HJ4+1 -> 45583 | HL4: =HK4+3 -> 45586 | HM4: =HL4+1 -> 45587 | HN4: =HM4+1 -> 45588 | HO4: =HN4+1 -> 45589 | HP4: =HO4+1 -> 45590 | HQ4: =HP4+3 -> 45593 | HR4: =HQ4+1 -> 45594 | HS4: =HR4+1 -> 45595 | HT4: =HS4+1 -> 45596 | HU4: =HT4+1 -> 45597 | HV4: =HU4+3 -> 45600 | HW4: =HV4+1 -> 45601 | HX4: =HW4+1 -> 45602 | HY4: =HX4+1 -> 45603 | HZ4: =HY4+1 -> 45604 | IA4: =HZ4+3 -> 45607 | IB4: =IA4+1 -> 45608 | IC4: =IB4+1 -> 45609 | ID4: =IC4+1 -> 45610 | IE4: =ID4+1 -> 45611 | IF4: =IE4+3 -> 45614 | IG4: =IF4+1 -> 45615 | IH4: =IG4+1 -> 45616 | II4: =IH4+1 -> 45617 | IJ4: =II4+1 -> 45618 | IK4: =IJ4+3 -> 45621 | IL4: =IK4+1 -> 45622 | IM4: =IL4+1 -> 45623 | IN4: =IM4+1 -> 45624 | IO4: =IN4+1 -> 45625 | IP4: =IO4+3 -> 45628 | IQ4: =IP4+1 -> 45629 | IR4: =IQ4+1 -> 45630 | IS4: =IR4+1 -> 45631 | IT4: =IS4+1 -> 45632 | IU4: =IT4+3 -> 45635 | IV4: =IU4+1 -> 45636 | IW4: =IV4+1 -> 45637 | IX4: =IW4+1 -> 45638 | IY4: =IX4+1 -> 45639 | IZ4: =IY4+3 -> 45642 | JA4: =IZ4+1 -> 45643 | JB4: =JA4+1 -> 45644 | JC4: =JB4+1 -> 45645 | JD4: =JC4+1 -> 45646 | JE4: =JD4+3 -> 45649 | JF4: =JE4+1 -> 45650 | JG4: =JF4+1 -> 45651 | JH4: =JG4+1 -> 45652 | JI4: =JH4+1 -> 45653 | JJ4: =JI4+3 -> 45656 | JK4: =JJ4+1 -> 45657 | JL4: =JK4+1 -> 45658 | JM4: =JL4+1 -> 45659 | JN4: =JM4+1 -> 45660 | JO4: =JN4+3 -> 45663 | JP4: =JO4+1 -> 45664 | JQ4: =JP4+1 -> 45665 | JR4: =JQ4+1 -> 45666 | JS4: =JR4+1 -> 45667 | JT4: =JS4+3 -> 45670 | JU4: =JT4+1 -> 45671 | JV4: =JU4+1 -> 45672 | JW4: =JV4+1 -> 45673 | JX4: =JW4+1 -> 45674 | JY4: =JX4+3 -> 45677 | JZ4: =JY4+1 -> 45678 | KA4: =JZ4+1 -> 45679 | KB4: =KA4+1 -> 45680 | KC4: =KB4+1 -> 45681 | KD4: =KC4+3 -> 45684 | KE4: =KD4+1 -> 45685 | KF4: =KE4+1 -> 45686 | KG4: =KF4+1 -> 45687 | KH4: =KG4+1 -> 45688 | KI4: =KH4+3 -> 45691 | KJ4: =KI4+1 -> 45692 | KK4: =KJ4+1 -> 45693 | KL4: =KK4+1 -> 45694 | KM4: =KL4+1 -> 45695 | KN4: =KM4+3 -> 45698 | KO4: =KN4+1 -> 45699 | KP4: =KO4+1 -> 45700 | KQ4: =KP4+1 -> 45701 | KR4: =KQ4+1 -> 45702 | KS4: =KR4+3 -> 45705 | KT4: =KS4+1 -> 45706 | KU4: =KT4+1 -> 45707 | KV4: =KU4+1 -> 45708 | KW4: =KV4+1 -> 45709 | KX4: =KW4+3 -> 45712 | KY4: =KX4+1 -> 45713 | KZ4: =KY4+1 -> 45714 | LA4: =KZ4+1 -> 45715 | LB4: =LA4+1 -> 45716 | LC4: =LB4+3 -> 45719 | LD4: =LC4+1 -> 45720 | LE4: =LD4+1 -> 45721 | LF4: =LE4+1 -> 45722 | LG4: =LF4+1 -> 45723 | LH4: =LG4+3 -> 45726 | LI4: =LH4+1 -> 45727 | LJ4: =LI4+1 -> 45728 | LK4: =LJ4+1 -> 45729 | LL4: =LK4+1 -> 45730 | LM4: =LL4+3 -> 45733 | LN4: =LM4+1 -> 45734 | LO4: =LN4+1 -> 45735 | LP4: =LO4+1 -> 45736 | LQ4: =LP4+1 -> 45737 | LR4: =LQ4+3 -> 45740 | LS4: =LR4+1 -> 45741 | LT4: =LS4+1 -> 45742 | LU4: =LT4+1 -> 45743 | LV4: =LU4+1 -> 45744 | LW4: =LV4+3 -> 45747 | LX4: =LW4+1 -> 45748 | LY4: =LX4+1 -> 45749 | LZ4: =LY4+1 -> 45750 | MA4: =LZ4+1 -> 45751 | MB4: =MA4+3 -> 45754 | MC4: =MB4+1 -> 45755 | MD4: =MC4+1 -> 45756 | ME4: =MD4+1 -> 45757 | MF4: =ME4+1 -> 45758 | MG4: =MF4+3 -> 45761 | MH4: =MG4+1 -> 45762 | MI4: =MH4+1 -> 45763 | MJ4: =MI4+1 -> 45764 | MK4: =MJ4+1 -> 45765 | ML4: =MK4+3 -> 45768 | MM4: =ML4+1 -> 45769 | MN4: =MM4+1 -> 45770 | MO4: =MN4+1 -> 45771 | MP4: =MO4+1 -> 45772 | MQ4: =MP4+3 -> 45775 | MR4: =MQ4+1 -> 45776 | MS4: =MR4+1 -> 45777 | MT4: =MS4+1 -> 45778 | MU4: =MT4+1 -> 45779 | MV4: =MU4+3 -> 45782 | MW4: =MV4+1 -> 45783 | MX4: =MW4+1 -> 45784 | MY4: =MX4+1 -> 45785 | MZ4: =MY4+1 -> 45786 | NA4: =MZ4+3 -> 45789 | NB4: =NA4+1 -> 45790 | NC4: =NB4+1 -> 45791 | ND4: =NC4+1 -> 45792 | NE4: =ND4+1 -> 45793 | NF4: =NE4+3 -> 45796 | NG4: =NF4+1 -> 45797 | NH4: =NG4+1 -> 45798 | NI4: =NH4+1 -> 45799 | NJ4: =NI4+1 -> 45800 | NK4: =NJ4+3 -> 45803 | NL4: =NK4+1 -> 45804 | NM4: =NL4+1 -> 45805 | NN4: =NM4+1 -> 45806 | NO4: =NN4+1 -> 45807 | NP4: =NO4+3 -> 45810 | NQ4: =NP4+1 -> 45811 | NR4: =NQ4+1 -> 45812 | NS4: =NR4+1 -> 45813 | NT4: =NS4+1 -> 45814 | NU4: =NT4+3 -> 45817 | NV4: =NU4+1 -> 45818 | NW4: =NV4+1 -> 45819 | NX4: =NW4+1 -> 45820 | NY4: =NX4+1 -> 45821 | NZ4: =NY4+3 -> 45824 | OA4: =NZ4+1 -> 45825 | OB4: =OA4+1 -> 45826 | OC4: =OB4+1 -> 45827 | OD4: =OC4+1 -> 45828 | OE4: =OD4+3 -> 45831 | OF4: =OE4+1 -> 45832 | OG4: =OF4+1 -> 45833 | OH4: =OG4+1 -> 45834 | OI4: =OH4+1 -> 45835 | OJ4: =OI4+3 -> 45838 | OK4: =OJ4+1 -> 45839 | OL4: =OK4+1 -> 45840 | OM4: =OL4+1 -> 45841 | ON4: =OM4+1 -> 45842 | OO4: =ON4+3 -> 45845 | OP4: =OO4+1 -> 45846 | OQ4: =OP4+1 -> 45847 | OR4: =OQ4+1 -> 45848 | OS4: =OR4+1 -> 45849 | OT4: =OS4+3 -> 45852 | OU4: =OT4+1 -> 45853 | OV4: =OU4+1 -> 45854 | OW4: =OV4+1 -> 45855 | OX4: =OW4+1 -> 45856 | OY4: =OX4+3 -> 45859 | OZ4: =OY4+1 -> 45860 | PA4: =OZ4+1 -> 45861 | PB4: =PA4+1 -> 45862 | PC4: =PB4+1 -> 45863 | PD4: =PC4+3 -> 45866 | PE4: =PD4+1 -> 45867 | PF4: =PE4+1 -> 45868 | PG4: =PF4+1 -> 45869 | PH4: =PG4+1 -> 45870 | PI4: =PH4+3 -> 45873 | PJ4: =PI4+1 -> 45874 | PK4: =PJ4+1 -> 45875 | PL4: =PK4+1 -> 45876 | PM4: =PL4+1 -> 45877 | PN4: =PM4+3 -> 45880 | PO4: =PN4+1 -> 45881 | PP4: =PO4+1 -> 45882 | PQ4: =PP4+1 -> 45883 | PR4: =PQ4+1 -> 45884 | PS4: =PR4+3 -> 45887 | PT4: =PS4+1 -> 45888 | PU4: =PT4+1 -> 45889 | PV4: =PU4+1 -> 45890 | PW4: =PV4+1 -> 45891 | PX4: =PW4+3 -> 45894 | PY4: =PX4+1 -> 45895 | PZ4: =PY4+1 -> 45896 | QA4: =PZ4+1 -> 45897 | QB4: =QA4+1 -> 45898 | QC4: =QB4+3 -> 45901 | QD4: =QC4+1 -> 45902 | QE4: =QD4+1 -> 45903 | QF4: =QE4+1 -> 45904 | QG4: =QF4+1 -> 45905 | QH4: =QG4+3 -> 45908 | QI4: =QH4+1 -> 45909 | QJ4: =QI4+1 -> 45910 | QK4: =QJ4+1 -> 45911 | QL4: =QK4+1 -> 45912 | QM4: =QL4+3 -> 45915 | QN4: =QM4+1 -> 45916 | QO4: =QN4+1 -> 45917 | QP4: =QO4+1 -> 45918 | QQ4: =QP4+1 -> 45919 | QR4: =QQ4+3 -> 45922 | QS4: =QR4+1 -> 45923 | QT4: =QS4+1 -> 45924 | QU4: =QT4+1 -> 45925 | QV4: =QU4+1 -> 45926 | QW4: =QV4+3 -> 45929 | QX4: =QW4+1 -> 45930 | QY4: =QX4+1 -> 45931 | QZ4: =QY4+1 -> 45932 | RA4: =QZ4+1 -> 45933 | RB4: =RA4+3 -> 45936 | RC4: =RB4+1 -> 45937 | RD4: =RC4+1 -> 45938 | RE4: =RD4+1 -> 45939 | RF4: =RE4+1 -> 45940 | RG4: =RF4+3 -> 45943 | RH4: =RG4+1 -> 45944 | RI4: =RH4+1 -> 45945 | RJ4: =RI4+1 -> 45946 | RK4: =RJ4+1 -> 45947 | RL4: =RK4+3 -> 45950 | RM4: =RL4+1 -> 45951 | RN4: =RM4+1 -> 45952 | RO4: =RN4+1 -> 45953 | RP4: =RO4+1 -> 45954 | RQ4: =RP4+3 -> 45957 | RR4: =RQ4+1 -> 45958 | RS4: =RR4+1 -> 45959 | RT4: =RS4+1 -> 45960 | RU4: =RT4+1 -> 45961 | RV4: =RU4+3 -> 45964 | RW4: =RV4+1 -> 45965 | RX4: =RW4+1 -> 45966 | RY4: =RX4+1 -> 45967 | RZ4: =RY4+1 -> 45968 | SA4: =RZ4+3 -> 45971 | SB4: =SA4+1 -> 45972 | SC4: =SB4+1 -> 45973 | SD4: =SC4+1 -> 45974 | SE4: =SD4+1 -> 45975 | SF4: =SE4+3 -> 45978 | SG4: =SF4+1 -> 45979 | SH4: =SG4+1 -> 45980 | SI4: =SH4+1 -> 45981 | SJ4: =SI4+1 -> 45982 | SK4: =SJ4+3 -> 45985 | SL4: =SK4+1 -> 45986 | SM4: =SL4+1 -> 45987 | SN4: =SM4+1 -> 45988 | SO4: =SN4+1 -> 45989 | SP4: =SO4+3 -> 45992 | SQ4: =SP4+1 -> 45993 | SR4: =SQ4+1 -> 45994 | SS4: =SR4+1 -> 45995 | ST4: =SS4+1 -> 45996 | SU4: =ST4+3 -> 45999 | SV4: =SU4+1 -> 46000 | SW4: =SV4+1 -> 46001 | SX4: =SW4+1 -> 46002 | SY4: =SX4+1 -> 46003 | SZ4: =SY4+3 -> 46006 | TA4: =SZ4+1 -> 46007 | TB4: =TA4+1 -> 46008 | TC4: =TB4+1 -> 46009 | TD4: =TC4+1 -> 46010 | TE4: =TD4+3 -> 46013 | TF4: =TE4+1 -> 46014 | TG4: =TF4+1 -> 46015 | TH4: =TG4+1 -> 46016 | TI4: =TH4+1 -> 46017
A5: 착수 | B5: 기획 | C5: 계약 | D5: 대상/더위버 | E5: 45614 | F5: 45632 | G5: =NETWORKDAYS.INTL(E5,F5,1,공휴일!$B$4:$B$15) -> 15 | H5: =IFERROR(MIN(1,(DATEDIF(E5,TODAY(),"d")+1)/(DATEDIF(E5,F5,"d")+1)),0) -> 1 | I5: 1
C6: 킥오프 | D6: 대상/더위버 | E6: 45631 | F6: 45631 | G6: =NETWORKDAYS.INTL(E6,F6,1,공휴일!$B$4:$B$15) -> 1 | H6: =IFERROR(MIN(1,(DATEDIF(E6,TODAY(),"d")+1)/(DATEDIF(E6,F6,"d")+1)),0) -> 1 | I6: 1
C7: 구축방향/요구사항정의 | D7: 대상/더위버 | E7: 45631 | F7: 45636 | G7: =NETWORKDAYS.INTL(E7,F7,1,공휴일!$B$4:$B$15) -> 4 | H7: =IFERROR(MIN(1,(DATEDIF(E7,TODAY(),"d")+1)/(DATEDIF(E7,F7,"d")+1)),0) -> 1 | I7: 1
C8: WBS수립 | D8: 더위버 | E8: 45625 | F8: 45636 | G8: =NETWORKDAYS.INTL(E8,F8,1,공휴일!$B$4:$B$15) -> 8 | H8: =IFERROR(MIN(1,(DATEDIF(E8,TODAY(),"d")+1)/(DATEDIF(E8,F8,"d")+1)),0) -> 1 | I8: 1
C9: IA설계 | D9: 더위버 | E9: 45625 | F9: 45638 | G9: =NETWORKDAYS.INTL(E9,F9,1,공휴일!$B$4:$B$15) -> 10 | H9: =IFERROR(MIN(1,(DATEDIF(E9,TODAY(),"d")+1)/(DATEDIF(E9,F9,"d")+1)),0) -> 1 | I9: 1
C10: 콘텐츠 수급 - About Us | D10: 대상 | E10: 45628 | F10: 45646 | G10: =NETWORKDAYS.INTL(E10,F10,1,공휴일!$B$4:$B$15) -> 15 | H10: =IFERROR(MIN(1,(DATEDIF(E10,TODAY(),"d")+1)/(DATEDIF(E10,F10,"d")+1)),0) -> 1 | I10: 1
C11: 콘텐츠 수급 - Brand | D11: 대상 | E11: 45628 | F11: 45737 | G11: =NETWORKDAYS.INTL(E11,F11,1,공휴일!$B$4:$B$15) -> 73 | H11: =IFERROR(MIN(1,(DATEDIF(E11,TODAY(),"d")+1)/(DATEDIF(E11,F11,"d")+1)),0) -> 1 | I11: 1
C12: 콘텐츠 수급 - R&D | D12: 대상 | E12: 45628 | F12: 45646 | G12: =NETWORKDAYS.INTL(E12,F12,1,공휴일!$B$4:$B$15) -> 15 | H12: =IFERROR(MIN(1,(DATEDIF(E12,TODAY(),"d")+1)/(DATEDIF(E12,F12,"d")+1)),0) -> 1 | I12: 1
C13: 콘텐츠 수급 - Media | D13: 대상 | E13: 45628 | F13: 45646 | G13: =NETWORKDAYS.INTL(E13,F13,1,공휴일!$B$4:$B$15) -> 15 | H13: =IFERROR(MIN(1,(DATEDIF(E13,TODAY(),"d")+1)/(DATEDIF(E13,F13,"d")+1)),0) -> 1 | I13: 1
C14: 콘텐츠 수급 - Support | D14: 대상 | E14: 45628 | F14: 45716 | G14: =NETWORKDAYS.INTL(E14,F14,1,공휴일!$B$4:$B$15) -> 59 | H14: =IFERROR(MIN(1,(DATEDIF(E14,TODAY(),"d")+1)/(DATEDIF(E14,F14,"d")+1)),0) -> 1 | I14: 1
C15: 콘텐츠 수급- 기타 | D15: 대상 | E15: 45628 | F15: 45646 | G15: =NETWORKDAYS.INTL(E15,F15,1,공휴일!$B$4:$B$15) -> 15 | H15: =IFERROR(MIN(1,(DATEDIF(E15,TODAY(),"d")+1)/(DATEDIF(E15,F15,"d")+1)),0) -> 1 | I15: 0.99
B16: 개발 | C16: 서버 환경 확인 및 설정 협의 | D16: 대상/더위버 | E16: 45635 | F16: 45646 | G16: =NETWORKDAYS.INTL(E16,F16,1,공휴일!$B$4:$B$15) -> 10 | H16: =IFERROR(MIN(1,(DATEDIF(E16,TODAY(),"d")+1)/(DATEDIF(E16,F16,"d")+1)),0) -> 1 | I16: 1
C17: 내부 개발 환경 세팅 | D17: 더위버 | E17: 45649 | F17: 45660 | G17: =NETWORKDAYS.INTL(E17,F17,1,공휴일!$B$4:$B$15) -> 8 | H17: =IFERROR(MIN(1,(DATEDIF(E17,TODAY(),"d")+1)/(DATEDIF(E17,F17,"d")+1)),0) -> 1 | I17: 1
A18: Admin | B18: 기획 | C18: 관리자 기능 정의 | D18: 더위버 | E18: 45649 | F18: 45667 | G18: =NETWORKDAYS.INTL(E18,F18,1,공휴일!$B$4:$B$15) -> 13 | H18: =IFERROR(MIN(1,(DATEDIF(E18,TODAY(),"d")+1)/(DATEDIF(E18,F18,"d")+1)),0) -> 1 | I18: 1
C19: 화면설계 | D19: 더위버 | E19: 45656 | F19: 45681 | G19: =NETWORKDAYS.INTL(E19,F19,1,공휴일!$B$4:$B$15) -> 19 | H19: =IFERROR(MIN(1,(DATEDIF(E19,TODAY(),"d")+1)/(DATEDIF(E19,F19,"d")+1)),0) -> 1 | I19: 0.9
B20: 개발 | C20: 설계/협의 | D20: 더위버 | E20: 45663 | F20: 45667 | G20: =NETWORKDAYS.INTL(E20,F20,1,공휴일!$B$4:$B$15) -> 5 | H20: =IFERROR(MIN(1,(DATEDIF(E20,TODAY(),"d")+1)/(DATEDIF(E20,F20,"d")+1)),0) -> 1 | I20: 1
C21: 관리자 개발 | D21: 더위버 | E21: 45670 | F21: 45730 | G21: =NETWORKDAYS.INTL(E21,F21,1,공휴일!$B$4:$B$15) -> 40 | H21: =IFERROR(MIN(1,(DATEDIF(E21,TODAY(),"d")+1)/(DATEDIF(E21,F21,"d")+1)),0) -> 1 | I21: 0.9
A22: Front | B22: 기획 | C22: 화면설계 - 메인 | D22: 더위버 | E22: 45642 | F22: 45650 | G22: =NETWORKDAYS.INTL(E22,F22,1,공휴일!$B$4:$B$15) -> 7 | H22: =IFERROR(MIN(1,(DATEDIF(E22,TODAY(),"d")+1)/(DATEDIF(E22,F22,"d")+1)),0) -> 1 | I22: 1
A23: 국문 | C23: 화면설계 - About Us | D23: 더위버 | E23: 45635 | F23: 45666 | G23: =NETWORKDAYS.INTL(E23,F23,1,공휴일!$B$4:$B$15) -> 22 | H23: =IFERROR(MIN(1,(DATEDIF(E23,TODAY(),"d")+1)/(DATEDIF(E23,F23,"d")+1)),0) -> 1 | I23: 1
C24: 화면설계 - Brand | D24: 더위버 | E24: 45635 | F24: 45666 | G24: =NETWORKDAYS.INTL(E24,F24,1,공휴일!$B$4:$B$15) -> 22 | H24: =IFERROR(MIN(1,(DATEDIF(E24,TODAY(),"d")+1)/(DATEDIF(E24,F24,"d")+1)),0) -> 1 | I24: 1
C25: 화면설계 - R&D | D25: 더위버 | E25: 45635 | F25: 45666 | G25: =NETWORKDAYS.INTL(E25,F25,1,공휴일!$B$4:$B$15) -> 22 | H25: =IFERROR(MIN(1,(DATEDIF(E25,TODAY(),"d")+1)/(DATEDIF(E25,F25,"d")+1)),0) -> 1 | I25: 1
C26: 화면설계 - Media&IR | D26: 더위버 | E26: 45635 | F26: 45666 | G26: =NETWORKDAYS.INTL(E26,F26,1,공휴일!$B$4:$B$15) -> 22 | H26: =IFERROR(MIN(1,(DATEDIF(E26,TODAY(),"d")+1)/(DATEDIF(E26,F26,"d")+1)),0) -> 1 | I26: 1
C27: 화면설계 - Support | D27: 더위버 | E27: 45635 | F27: 45666 | G27: =NETWORKDAYS.INTL(E27,F27,1,공휴일!$B$4:$B$15) -> 22 | H27: =IFERROR(MIN(1,(DATEDIF(E27,TODAY(),"d")+1)/(DATEDIF(E27,F27,"d")+1)),0) -> 1 | I27: 1
C28: 화면설계 - 기타 | D28: 더위버 | E28: 45645 | F28: 45653 | G28: =NETWORKDAYS.INTL(E28,F28,1,공휴일!$B$4:$B$15) -> 6 | H28: =IFERROR(MIN(1,(DATEDIF(E28,TODAY(),"d")+1)/(DATEDIF(E28,F28,"d")+1)),0) -> 1 | I28: 1
C29: 콘텐츠 검수 및 심의 | D29: 대상 | E29: 45659 | F29: 45734 | G29: =NETWORKDAYS.INTL(E29,F29,1,공휴일!$B$4:$B$15) -> 49 | H29: =IFERROR(MIN(1,(DATEDIF(E29,TODAY(),"d")+1)/(DATEDIF(E29,F29,"d")+1)),0) -> 1 | I29: 0.9
B30: 디자인 | C30: 실행안 제작 - 메인 | D30: 더위버 | E30: 45635 | F30: 45679 | G30: =NETWORKDAYS.INTL(E30,F30,1,공휴일!$B$4:$B$15) -> 31 | H30: =IFERROR(MIN(1,(DATEDIF(E30,TODAY(),"d")+1)/(DATEDIF(E30,F30,"d")+1)),0) -> 1 | I30: 1
C31: 실행안 제작 - 서브 | D31: 더위버 | E31: 45635 | F31: 45679 | G31: =NETWORKDAYS.INTL(E31,F31,1,공휴일!$B$4:$B$15) -> 31 | H31: =IFERROR(MIN(1,(DATEDIF(E31,TODAY(),"d")+1)/(DATEDIF(E31,F31,"d")+1)),0) -> 1 | I31: 1
C32: 스타일 가이드 제작 | D32: 더위버 | E32: 45649 | F32: 45681 | G32: =NETWORKDAYS.INTL(E32,F32,1,공휴일!$B$4:$B$15) -> 23 | H32: =IFERROR(MIN(1,(DATEDIF(E32,TODAY(),"d")+1)/(DATEDIF(E32,F32,"d")+1)),0) -> 1 | I32: 1
C33: 페이지 디자인 - 메인 | D33: 더위버 | E33: 45705 | F33: 45709 | G33: =NETWORKDAYS.INTL(E33,F33,1,공휴일!$B$4:$B$15) -> 5 | H33: =IFERROR(MIN(1,(DATEDIF(E33,TODAY(),"d")+1)/(DATEDIF(E33,F33,"d")+1)),0) -> 1 | I33: 1
C34: 페이지 디자인 - About Us | D34: 더위버 | E34: 45677 | F34: 45716 | G34: =NETWORKDAYS.INTL(E34,F34,1,공휴일!$B$4:$B$15) -> 26 | H34: =IFERROR(MIN(1,(DATEDIF(E34,TODAY(),"d")+1)/(DATEDIF(E34,F34,"d")+1)),0) -> 1 | I34: 1
C35: 페이지 디자인 - Brand | D35: 더위버 | E35: 45677 | F35: 45713 | G35: =NETWORKDAYS.INTL(E35,F35,1,공휴일!$B$4:$B$15) -> 23 | H35: =IFERROR(MIN(1,(DATEDIF(E35,TODAY(),"d")+1)/(DATEDIF(E35,F35,"d")+1)),0) -> 1 | I35: 1
C36: 페이지 디자인 - R&D | D36: 더위버 | E36: 45705 | F36: 45716 | G36: =NETWORKDAYS.INTL(E36,F36,1,공휴일!$B$4:$B$15) -> 10 | H36: =IFERROR(MIN(1,(DATEDIF(E36,TODAY(),"d")+1)/(DATEDIF(E36,F36,"d")+1)),0) -> 1 | I36: 1
C37: 페이지 디자인 - Media&IR | D37: 더위버 | E37: 45666 | F37: 45679 | G37: =NETWORKDAYS.INTL(E37,F37,1,공휴일!$B$4:$B$15) -> 10 | H37: =IFERROR(MIN(1,(DATEDIF(E37,TODAY(),"d")+1)/(DATEDIF(E37,F37,"d")+1)),0) -> 1 | I37: 1
C38: 페이지 디자인 - Support | D38: 더위버 | E38: 45666 | F38: 45679 | G38: =NETWORKDAYS.INTL(E38,F38,1,공휴일!$B$4:$B$15) -> 10 | H38: =IFERROR(MIN(1,(DATEDIF(E38,TODAY(),"d")+1)/(DATEDIF(E38,F38,"d")+1)),0) -> 1 | I38: 1
C39: 페이지 디자인 - Support(Wellife Solution) | D39: 더위버 | E39: 45698 | F39: 45702 | G39: =NETWORKDAYS.INTL(E39,F39,1,공휴일!$B$4:$B$15) -> 5 | H39: =IFERROR(MIN(1,(DATEDIF(E39,TODAY(),"d")+1)/(DATEDIF(E39,F39,"d")+1)),0) -> 1 | I39: 1
C40: 페이지 디자인 - 기타 | D40: 더위버 | E40: 45726 | F40: 45728 | G40: =NETWORKDAYS.INTL(E40,F40,1,공휴일!$B$4:$B$15) -> 3 | H40: =IFERROR(MIN(1,(DATEDIF(E40,TODAY(),"d")+1)/(DATEDIF(E40,F40,"d")+1)),0) -> 1 | I40: 1
...

Sheet V0.7
A1: 대상웰라이프_WBS
A2: ▥ Last update : | B2: 45712
A3: 구분 | C3: 세부 업무 항목 | D3: 담당 | E3: 시작일 | F3: 종료일 | G3: 기간 | H3: 날짜기준 진척률 | I3: 실제 진척률 | J3: 1월 | AF3: 2월 | AZ3: 3월 | BW3: 4월 | CQ3: 5월 | DN3: 6월 | EJ3: 7월 | FE3: 8월 | GB3: 9월 | GW3: 10월 | HS3: 11월 | IO3: 12월 | JJ3: 1월 | KF3: 2월 | KZ3: 3월 | LW3: 4월 | MQ3: 5월 | NN3: 6월 | OJ3: 7월 | PE3: 8월 | QB3: 9월 | QW3: 10월 | RS3: 11월 | SO3: 12월
